<mujoco model="biped_s4">
  <compiler angle="radian" meshdir="../meshes/"/>
  <asset>
    <mesh name="torso" file="torso.obj"/>
    <mesh name="l_leg_roll" file="l_leg_roll.obj"/>
    <mesh name="l_leg_yaw" file="l_leg_yaw.obj"/>
    <mesh name="l_leg_pitch" file="l_leg_pitch.obj"/>
    <mesh name="l_knee" file="l_knee.obj"/>
    <mesh name="l_foot_pitch" file="l_foot_pitch.obj"/>
    <mesh name="l_foot_roll" file="l_foot_roll.obj"/>
    <mesh name="r_leg_roll" file="r_leg_roll.obj"/>
    <mesh name="r_leg_yaw" file="r_leg_yaw.obj"/>
    <mesh name="r_leg_pitch" file="r_leg_pitch.obj"/>
    <mesh name="r_knee" file="r_knee.obj"/>
    <mesh name="r_foot_pitch" file="r_foot_pitch.obj"/>
    <mesh name="r_foot_roll" file="r_foot_roll.obj"/>
    <mesh name="l_arm_pitch" file="l_arm_pitch.obj"/>
    <mesh name="l_arm_roll" file="l_arm_roll.obj"/>
    <mesh name="l_arm_yaw" file="l_arm_yaw.obj"/>
    <mesh name="l_forearm_pitch" file="l_forearm_pitch.obj"/>
    <mesh name="l_hand_yaw" file="l_hand_yaw.obj"/>
    <mesh name="l_hand_pitch" file="l_hand_pitch.obj"/>
    <mesh name="l_hand_roll" file="l_hand_roll.STL"/>
    <mesh name="r_arm_pitch" file="r_arm_pitch.obj"/>
    <mesh name="r_arm_roll" file="r_arm_roll.obj"/>
    <mesh name="r_arm_yaw" file="r_arm_yaw.obj"/>
    <mesh name="r_forearm_pitch" file="r_forearm_pitch.obj"/>
    <mesh name="r_hand_yaw" file="r_hand_yaw.obj"/>
    <mesh name="r_hand_pitch" file="r_hand_pitch.obj"/>
    <mesh name="r_hand_roll" file="r_hand_roll.STL"/>
    <mesh name="head_yaw" file="head_yaw.STL"/>
    <mesh name="head_pitch" file="head_pitch.STL"/>
    <mesh name="l_thumb_proximal_yaw" file="l_thumb_proximal_yaw.STL"/>
    <mesh name="l_thumb_distal_pitch" file="l_thumb_distal_pitch.STL"/>
    <mesh name="l_index_proximal_finger" file="l_index_proximal_finger.STL"/>
    <mesh name="l_index_distal_finger" file="l_index_distal_finger.STL"/>
    <mesh name="l_middle_proximal_finger" file="l_middle_proximal_finger.STL"/>
    <mesh name="l_middle_distal_finger" file="l_middle_distal_finger.STL"/>
    <mesh name="l_ring_proximal_finger" file="l_ring_proximal_finger.STL"/>
    <mesh name="l_ring_distal_finger" file="l_ring_distal_finger.STL"/>
    <mesh name="l_pinky_proximal_finger" file="l_pinky_proximal_finger.STL"/>
    <mesh name="l_pinky_distal_finger" file="l_pinky_distal_finger.STL"/>
    <mesh name="r_thumb_proximal_yaw" file="r_thumb_proximal_yaw.STL"/>
    <mesh name="r_thumb_distal_pitch" file="r_thumb_distal_pitch.STL"/>
    <mesh name="r_index_proximal_finger" file="r_index_proximal_finger.STL"/>
    <mesh name="r_index_distal_finger" file="r_index_distal_finger.STL"/>
    <mesh name="r_middle_proximal_finger" file="r_middle_proximal_finger.STL"/>
    <mesh name="r_middle_distal_finger" file="r_middle_distal_finger.STL"/>
    <mesh name="r_ring_proximal_finger" file="r_ring_proximal_finger.STL"/>
    <mesh name="r_ring_distal_finger" file="r_ring_distal_finger.STL"/>
    <mesh name="r_pinky_proximal_finger" file="r_pinky_proximal_finger.STL"/>
    <mesh name="r_pinky_distal_finger" file="r_pinky_distal_finger.STL"/>
  </asset>
  <worldbody>
    <geom type="mesh" contype="0" conaffinity="0" group="1" density="0" rgba="1 1 1 1" mesh="torso"/>
    <geom size="0.001" pos="0.11416 0.0175 0.28459" quat="0.936736 0 0.350037 0" contype="0" conaffinity="0" group="1" density="0" rgba="1 1 1 1"/>
    <geom pos="-0.0175476 0 0.4994" type="mesh" contype="0" conaffinity="0" group="1" density="0" rgba="0.6902 0.65882 0.63922 1" mesh="head_yaw"/>
    <geom pos="-0.0175476 0 0.4994" type="mesh" rgba="0.6902 0.65882 0.63922 1" mesh="head_yaw"/>
    <geom pos="-0.0175476 0 0.4994" type="mesh" contype="0" conaffinity="0" group="1" density="0" rgba="0.6902 0.65882 0.63922 1" mesh="head_pitch"/>
    <geom pos="-0.0175476 0 0.4994" type="mesh" rgba="0.6902 0.65882 0.63922 1" mesh="head_pitch"/>
    <geom size="0.001" pos="0.0644524 0.0175 0.55389" quat="0.953764 0 0.300558 0" contype="0" conaffinity="0" group="1" density="0" rgba="0.6902 0.65882 0.63922 1"/>
    <body name="leg_l1_link" pos="-0.139 0.088087 -0.065549">
      <inertial pos="0.0661423 -1.19e-06 -0.00862806" quat="-0.00036611 0.685786 0.000388541 0.727803" mass="1.53801" diaginertia="0.00367033 0.00282649 0.00188822"/>
      <joint name="leg_l1_joint" pos="0 0 0" axis="1 0 0" range="-0.31 0.66" actuatorfrcrange="-85 85"/>
      <geom type="mesh" contype="0" conaffinity="0" group="1" density="0" rgba="0.6902 0.65882 0.63922 1" mesh="l_leg_roll"/>
      <body name="leg_l2_link" pos="0.1365 -0.0010866 -0.033901">
        <inertial pos="0 0.046104 -0.132561" quat="0.406465 0.913665 0.00146124 -0.000707497" mass="1.60097" diaginertia="0.0069836 0.00577369 0.00365952"/>
        <joint name="leg_l2_joint" pos="0 0 0" axis="0 0 1" range="-0.52 1.04" actuatorfrcrange="-60 60"/>
        <geom type="mesh" contype="0" conaffinity="0" group="1" density="0" rgba="0.65098 0.61961 0.58824 1" mesh="l_leg_yaw"/>
        <body name="leg_l3_link" pos="0 0.094 -0.09">
          <inertial pos="-0.00644903 -0.0981356 -0.0535761" quat="0.680972 -0.0265435 0.0402869 0.730718" mass="2.46657" diaginertia="0.0233349 0.022619 0.00397939"/>
          <joint name="leg_l3_joint" pos="0 0 0" axis="0 1 0" range="-1.83 1.04" actuatorfrcrange="-85 85"/>
          <geom type="mesh" contype="0" conaffinity="0" group="1" density="0" rgba="0.52941 0.54902 0.54902 1" mesh="l_leg_pitch"/>
          <body name="leg_l4_link" pos="0.004136 -0.06635 -0.24997">
            <inertial pos="0.00080045 -4.225e-05 -0.120497" quat="0.708481 -0.000629386 -0.0108666 0.705646" mass="1.62912" diaginertia="0.013595 0.0134393 0.000915523"/>
            <joint name="leg_l4_joint" pos="0 0 0" axis="0 1 0" range="0 2.18" actuatorfrcrange="-85 85"/>
            <geom type="mesh" contype="0" conaffinity="0" group="1" density="0" rgba="0.68627 0.65882 0.63922 1" mesh="l_knee"/>
            <body name="leg_l5_link" pos="0 -0.0022 -0.346">
              <inertial pos="0 -0.0209998 0" quat="0.5 0.5 -0.5 0.5" mass="0.0544445" diaginertia="7.28e-06 4.11e-06 4.11e-06"/>
              <joint name="leg_l5_joint" pos="0 0 0" axis="0 1 0" range="-0.61 0.52" actuatorfrcrange="-36 36"/>
              <geom type="mesh" contype="0" conaffinity="0" group="1" density="0" rgba="0.6902 0.65882 0.63922 1" mesh="l_foot_pitch"/>
              <body name="leg_l6_link">
                <inertial pos="-0.0355077 9.71466e-06 -0.0272597" quat="-0.000229205 0.628048 -0.000281424 0.778175" mass="0.470217" diaginertia="0.00146681 0.00133526 0.000364416"/>
                <joint name="leg_l6_joint" pos="0 0 0" axis="1 0 0" range="-0.61 0.52" actuatorfrcrange="-36 36"/>
                <geom type="mesh" contype="0" conaffinity="0" group="1" density="0" rgba="0.6902 0.65882 0.63922 1" mesh="l_foot_roll"/>
                <geom size="0.005" pos="-0.09 0.05 -0.0465" contype="0" conaffinity="0" group="1" density="0" rgba="0.6902 0.65882 0.63922 1"/>
                <geom size="0.005" pos="-0.09 0.05 -0.0465" rgba="0.6902 0.65882 0.63922 1"/>
                <geom size="0.005" pos="-0.09 -0.05 -0.0465" contype="0" conaffinity="0" group="1" density="0" rgba="0.6902 0.65882 0.63922 1"/>
                <geom size="0.005" pos="-0.09 -0.05 -0.0465" rgba="0.6902 0.65882 0.63922 1"/>
                <geom size="0.005" pos="0.15 0.05 -0.0465" contype="0" conaffinity="0" group="1" density="0" rgba="0.6902 0.65882 0.63922 1"/>
                <geom size="0.005" pos="0.15 0.05 -0.0465" rgba="0.6902 0.65882 0.63922 1"/>
                <geom size="0.005" pos="0.15 -0.05 -0.0465" contype="0" conaffinity="0" group="1" density="0" rgba="0.6902 0.65882 0.63922 1"/>
                <geom size="0.005" pos="0.15 -0.05 -0.0465" rgba="0.6902 0.65882 0.63922 1"/>
                <geom size="0.005" pos="0.15 0.05 -0.0465"/>
                <geom size="0.005" pos="-0.09 0.05 -0.0465"/>
                <geom size="0.005" pos="0.15 -0.05 -0.0465"/>
                <geom size="0.005" pos="-0.09 -0.05 -0.0465"/>
                <geom size="0.005" pos="0.15 0 -0.0465"/>
                <geom size="0.005" pos="-0.09 0 -0.0465"/>
              </body>
            </body>
          </body>
        </body>
      </body>
    </body>
    <body name="leg_r1_link" pos="-0.139 -0.088087 -0.065549">
      <inertial pos="0.0661423 1.19e-06 -0.00862806" quat="0.000366114 0.685786 -0.000388545 0.727803" mass="1.53801" diaginertia="0.00367033 0.00282648 0.00188822"/>
      <joint name="leg_r1_joint" pos="0 0 0" axis="1 0 0" range="-0.6629 0.314" actuatorfrcrange="-85 85"/>
      <geom type="mesh" contype="0" conaffinity="0" group="1" density="0" rgba="0.6902 0.65882 0.63922 1" mesh="r_leg_roll"/>
      <body name="leg_r2_link" pos="0.1365 0.0010866 -0.033901">
        <inertial pos="4.661e-05 -0.0461036 -0.132574" quat="0.928414 0.371529 0.00156279 -0.00347123" mass="1.60097" diaginertia="0.00520443 0.00457962 0.00331423"/>
        <joint name="leg_r2_joint" pos="0 0 0" axis="0 0 1" range="-1.04 0.52" actuatorfrcrange="-60 60"/>
        <geom type="mesh" contype="0" conaffinity="0" group="1" density="0" rgba="0.65098 0.619608 0.588235 1" mesh="r_leg_yaw"/>
        <body name="leg_r3_link" pos="0 -0.094 -0.09">
          <inertial pos="-0.00644903 0.0981356 -0.0535761" quat="0.782763 0.0509103 -0.043864 0.618681" mass="2.46657" diaginertia="0.0236078 0.0224895 0.00397676"/>
          <joint name="leg_r3_joint" pos="0 0 0" axis="0 1 0" range="-1.83 1.04" actuatorfrcrange="-85 85"/>
          <geom type="mesh" contype="0" conaffinity="0" group="1" density="0" rgba="0.529412 0.54902 0.54902 1" mesh="r_leg_pitch"/>
          <body name="leg_r4_link" pos="0.004136 0.06635 -0.24997">
            <inertial pos="0.00080045 4.225e-05 -0.120497" quat="0.705646 -0.0108666 -0.000629386 0.708481" mass="1.62912" diaginertia="0.013595 0.0134393 0.000915523"/>
            <joint name="leg_r4_joint" pos="0 0 0" axis="0 1 0" range="0 2.18" actuatorfrcrange="-85 85"/>
            <geom type="mesh" contype="0" conaffinity="0" group="1" density="0" rgba="0.686275 0.658824 0.639216 1" mesh="r_knee"/>
            <body name="leg_r5_link" pos="0 0.0022 -0.346">
              <inertial pos="0 0.0210002 0" quat="0.5 0.5 -0.5 0.5" mass="0.0544445" diaginertia="7.28e-06 4.11e-06 4.11e-06"/>
              <joint name="leg_r5_joint" pos="0 0 0" axis="0 1 0" range="-0.61 0.52" actuatorfrcrange="-36 36"/>
              <geom type="mesh" contype="0" conaffinity="0" group="1" density="0" rgba="0.690196 0.658824 0.639216 1" mesh="r_foot_pitch"/>
              <body name="leg_r6_link">
                <inertial pos="-0.0355078 -9.65506e-06 -0.0272597" quat="0.00022933 0.628048 0.00028129 0.778175" mass="0.470216" diaginertia="0.0014668 0.00133526 0.000364406"/>
                <joint name="leg_r6_joint" pos="0 0 0" axis="1 0 0" range="-0.52 0.61" actuatorfrcrange="-36 36"/>
                <geom type="mesh" contype="0" conaffinity="0" group="1" density="0" rgba="0.690196 0.658824 0.639216 1" mesh="r_foot_roll"/>
                <geom size="0.005" pos="-0.09 0.05 -0.0465" contype="0" conaffinity="0" group="1" density="0" rgba="0.690196 0.658824 0.639216 1"/>
                <geom size="0.005" pos="-0.09 0.05 -0.0465" rgba="0.690196 0.658824 0.639216 1"/>
                <geom size="0.005" pos="-0.09 -0.05 -0.0465" contype="0" conaffinity="0" group="1" density="0" rgba="0.690196 0.658824 0.639216 1"/>
                <geom size="0.005" pos="-0.09 -0.05 -0.0465" rgba="0.690196 0.658824 0.639216 1"/>
                <geom size="0.005" pos="0.15 0.05 -0.0465" contype="0" conaffinity="0" group="1" density="0" rgba="0.690196 0.658824 0.639216 1"/>
                <geom size="0.005" pos="0.15 0.05 -0.0465" rgba="0.690196 0.658824 0.639216 1"/>
                <geom size="0.005" pos="0.15 -0.05 -0.0465" contype="0" conaffinity="0" group="1" density="0" rgba="0.690196 0.658824 0.639216 1"/>
                <geom size="0.005" pos="0.15 -0.05 -0.0465" rgba="0.690196 0.658824 0.639216 1"/>
                <geom size="0.005" pos="0.15 0.05 -0.0465"/>
                <geom size="0.005" pos="-0.09 0.05 -0.0465"/>
                <geom size="0.005" pos="0.15 -0.05 -0.0465"/>
                <geom size="0.005" pos="-0.09 -0.05 -0.0465"/>
                <geom size="0.005" pos="0.15 0 -0.0465"/>
                <geom size="0.005" pos="-0.09 0 -0.0465"/>
              </body>
            </body>
          </body>
        </body>
      </body>
    </body>
    <body name="zarm_l1_link" pos="-0.0175476 0.2547 0.3245">
      <inertial pos="0.0146835 -0.0166604 -6.82857e-05" quat="0.696586 0.712206 -0.0625859 -0.0601207" mass="0.794" diaginertia="0.000271947 0.000196224 0.000121256"/>
      <joint name="zarm_l1_joint" pos="0 0 0" axis="0 1 0" range="-2.0933 0.5233" actuatorfrcrange="-60 60"/>
      <geom type="mesh" contype="0" conaffinity="0" group="1" density="0" rgba="1 1 1 1" mesh="l_arm_pitch"/>
      <body name="zarm_l2_link">
        <inertial pos="0.0222873 0.0156946 -0.0202262" quat="0.398328 0.58059 0.26378 0.659295" mass="0.20735" diaginertia="0.000283338 0.000217951 0.000157462"/>
        <joint name="zarm_l2_joint" pos="0 0 0" axis="1 0 0" range="-0.3489 2.0933" actuatorfrcrange="-82.8 82.8"/>
        <geom type="mesh" contype="0" conaffinity="0" group="1" density="0" rgba="1 1 1 1" mesh="l_arm_roll"/>
        <body name="zarm_l3_link">
          <inertial pos="6.1694e-05 0.00525815 -0.128822" quat="0.237126 0.666158 0.237177 0.666147" mass="1.12063" diaginertia="9.38963e-05 7.96873e-05 7.00576e-05"/>
          <joint name="zarm_l3_joint" pos="0 0 0" axis="0 0 1" range="-1.57 1.57" actuatorfrcrange="-60 60"/>
          <geom type="mesh" contype="0" conaffinity="0" group="1" density="0" rgba="1 1 1 1" mesh="l_arm_yaw"/>
          <body name="zarm_l4_link" pos="0 0 -0.1636">
            <inertial pos="-1.42819e-05 0.00938314 -0.0522688" quat="0.632873 0.313955 0.634285 0.313985" mass="0.395825" diaginertia="0.00013362 0.000113739 9.55807e-05"/>
            <joint name="zarm_l4_joint" pos="0 0 0" axis="0 1 0" range="-2.0933 0" actuatorfrcrange="-60 60"/>
            <geom type="mesh" contype="0" conaffinity="0" group="1" density="0" rgba="1 1 1 1" mesh="l_forearm_pitch"/>
            <body name="zarm_l5_link" pos="0 0 -0.19105">
              <inertial pos="0.000113133 0.00969228 0.0817961" quat="0.493085 0.506908 0.492087 0.507703" mass="0.380792" diaginertia="0.000122264 8.44608e-05 7.64924e-05"/>
              <joint name="zarm_l5_joint" pos="0 0 0" axis="0 0 1" range="-1.657 1.657" actuatorfrcrange="-6 6"/>
              <geom type="mesh" contype="0" conaffinity="0" group="1" density="0" rgba="1 1 1 1" mesh="l_hand_yaw"/>
              <body name="zarm_l6_link">
                <inertial pos="0.0081061 0.00489663 0.00622489" quat="0.972746 -0.202646 -0.0967872 0.0577326" mass="0.376651" diaginertia="4.90153e-05 3.61802e-05 2.19136e-05"/>
                <joint name="zarm_l6_joint" pos="0 0 0" axis="0 1 0" range="-1.657 1.657" actuatorfrcrange="-6 6"/>
                <geom type="mesh" contype="0" conaffinity="0" group="1" density="0" rgba="1 1 1 1" mesh="l_hand_pitch"/>
                <body name="zarm_l7_link">
                  <inertial pos="0.00557087 0.00644656 -0.0826894" quat="0.378878 0.570642 0.285709 0.670216" mass="0.705193" diaginertia="0.000126318 0.000107575 8.42004e-05"/>
                  <joint name="zarm_l7_joint" pos="0 0 0" axis="1 0 0" range="-1.57 1.57" actuatorfrcrange="-6 6"/>
                  <geom type="mesh" contype="0" conaffinity="0" group="1" density="0" rgba="1 1 1 1" mesh="l_hand_roll"/>
                  <geom size="0.005" pos="0 -0.03 -0.17"/>
                  <body name="l_thumb_proximal_yaw" pos="0.025 -0.0216278 -0.1107">
                    <inertial pos="0.00590167 -0.00373751 0.000119122" quat="0.600132 0.648007 0.296079 0.363683" mass="0.00177458" diaginertia="1.00106e-07 9.8657e-08 3.43995e-08"/>
                    <joint name="l_thumb_proximal_yaw_joint" pos="0 0 0" axis="0 0 -1"/>
                    <geom type="mesh" contype="0" conaffinity="0" group="1" density="0" rgba="1 1 1 0.25" mesh="l_thumb_proximal_yaw"/>
                    <geom type="mesh" rgba="1 1 1 0.25" mesh="l_thumb_proximal_yaw"/>
                    <body name="l_thumb_distal_pitch" pos="0.012 -0.0065 0">
                      <inertial pos="0.00835401 -1.54981e-06 -0.0372051" quat="0.999868 -1.94083e-06 0.0162762 -0.000119228" mass="0.0143595" diaginertia="7.16051e-06 6.87911e-06 9.08132e-07"/>
                      <joint name="l_thumb_distal_pitch_joint" pos="0 0 0" axis="0 1 0"/>
                      <geom type="mesh" contype="0" conaffinity="0" group="1" density="0" rgba="1 1 1 1" mesh="l_thumb_distal_pitch"/>
                      <geom type="mesh" rgba="1 1 1 1" mesh="l_thumb_distal_pitch"/>
                    </body>
                  </body>
                  <body name="l_index_proximal_finger" pos="0.0295025 0.00394879 -0.174731" quat="0.999879 0 -0.0155832 0">
                    <inertial pos="0.000112678 0.00210468 -0.0171028" quat="0.724188 0.05274 -0.0554585 0.685343" mass="0.00213737" diaginertia="3.47926e-07 3.18535e-07 9.08141e-08"/>
                    <joint name="l_index_proximal_finger_joint" pos="0 0 0" axis="-0.998506 0.0546396 0"/>
                    <geom type="mesh" contype="0" conaffinity="0" group="1" density="0" rgba="1 1 1 1" mesh="l_index_proximal_finger"/>
                    <geom type="mesh" rgba="1 1 1 1" mesh="l_index_proximal_finger"/>
                    <body name="l_index_distal_finger" pos="0.000133519 0.00243999 -0.0349146">
                      <inertial pos="-8.804e-05 -0.00161951 -0.0254572" quat="0.726308 -0.0166814 0.0176103 0.686942" mass="0.00504466" diaginertia="7.81738e-07 7.63459e-07 1.138e-07"/>
                      <joint name="l_index_distal_finger_joint" pos="0 0 0" axis="0.998506 -0.0546396 0"/>
                      <geom type="mesh" contype="0" conaffinity="0" group="1" density="0" rgba="1 1 1 1" mesh="l_index_distal_finger"/>
                      <geom type="mesh" rgba="1 1 1 1" mesh="l_index_distal_finger"/>
                    </body>
                  </body>
                  <body name="l_middle_proximal_finger" pos="0.0085 0.00820382 -0.178435">
                    <inertial pos="-8.42681e-08 0.0027021 -0.020783" quat="0.705466 0.0478411 -0.0478411 0.705507" mass="0.00260456" diaginertia="5.44468e-07 5.09608e-07 1.18037e-07"/>
                    <joint name="l_middle_proximal_finger_joint" pos="0 0 0" axis="-1 0 0"/>
                    <geom type="mesh" contype="0" conaffinity="0" group="1" density="0" rgba="1 1 1 1" mesh="l_middle_proximal_finger"/>
                    <geom type="mesh" rgba="1 1 1 1" mesh="l_middle_proximal_finger"/>
                    <body name="l_middle_distal_finger" pos="0 0.00292977 -0.0418977">
                      <inertial pos="6.04649e-07 -0.00162351 -0.0254572" quat="0.707266 -0.0171778 0.0171703 0.70653" mass="0.00504467" diaginertia="7.81735e-07 7.63455e-07 1.13799e-07"/>
                      <joint name="l_middle_distal_finger_joint" pos="0 0 0" axis="1 0 0"/>
                      <geom type="mesh" contype="0" conaffinity="0" group="1" density="0" rgba="1 1 1 1" mesh="l_middle_distal_finger"/>
                      <geom type="mesh" rgba="1 1 1 1" mesh="l_middle_distal_finger"/>
                    </body>
                  </body>
                  <body name="l_ring_proximal_finger" pos="-0.0126025 0.00807856 -0.176447" quat="0.999879 0 0.0155832 0">
                    <inertial pos="-0.000147797 0.00269935 -0.0207828" quat="0.68592 0.0491526 -0.0465376 0.724522" mass="0.00260456" diaginertia="5.44468e-07 5.09608e-07 1.18037e-07"/>
                    <joint name="l_ring_proximal_finger_joint" pos="0 0 0" axis="-0.998506 -0.0546396 0"/>
                    <geom type="mesh" contype="0" conaffinity="0" group="1" density="0" rgba="1 1 1 1" mesh="l_ring_proximal_finger"/>
                    <geom type="mesh" rgba="1 1 1 1" mesh="l_ring_proximal_finger"/>
                    <body name="l_ring_distal_finger" pos="-0.000160223 0.00292799 -0.0418975">
                      <inertial pos="-2.9782e-05 0.000551723 -0.0145821" quat="0.68743 -0.00980338 0.00928923 0.726125" mass="0.00182871" diaginertia="2.76151e-07 2.63479e-07 4.68186e-08"/>
                      <joint name="l_ring_distal_finger_joint" pos="0 0 0" axis="0.998506 0.0546396 0"/>
                      <geom type="mesh" contype="0" conaffinity="0" group="1" density="0" rgba="1 1 1 1" mesh="l_ring_distal_finger"/>
                      <geom type="mesh" rgba="1 1 1 1" mesh="l_ring_distal_finger"/>
                    </body>
                  </body>
                  <body name="l_pinky_proximal_finger" pos="-0.0332309 0.00363387 -0.170227" quat="0.999456 0 0.0329919 0">
                    <inertial pos="-0.000122637 0.00210213 -0.0171031" quat="0.684777 0.05571 -0.0523881 0.724729" mass="0.00213738" diaginertia="3.47927e-07 3.18535e-07 9.08146e-08"/>
                    <joint name="l_pinky_proximal_finger_joint" pos="0 0 0" axis="-0.99837 -0.0570678 0"/>
                    <geom type="mesh" contype="0" conaffinity="0" group="1" density="0" rgba="1 1 1 1" mesh="l_pinky_proximal_finger"/>
                    <geom type="mesh" rgba="1 1 1 1" mesh="l_pinky_proximal_finger"/>
                    <body name="l_pinky_distal_finger" pos="-0.000139217 0.00243553 -0.0349149">
                      <inertial pos="-2.37672e-05 0.000794235 -0.012715" quat="0.686968 -0.00436666 0.00172116 0.726672" mass="0.00162998" diaginertia="1.94746e-07 1.83819e-07 3.94562e-08"/>
                      <joint name="l_pinky_distal_finger_joint" pos="0 0 0" axis="0.99837 0.0570678 0"/>
                      <geom type="mesh" contype="0" conaffinity="0" group="1" density="0" rgba="1 1 1 1" mesh="l_pinky_distal_finger"/>
                      <geom type="mesh" rgba="1 1 1 1" mesh="l_pinky_distal_finger"/>
                    </body>
                  </body>
                </body>
              </body>
            </body>
          </body>
        </body>
      </body>
    </body>
    <body name="zarm_r1_link" pos="-0.0175476 -0.2547 0.3245">
      <inertial pos="0.0146744 0.0168298 -8.16712e-05" quat="0.712375 0.696324 0.0605536 0.0631598" mass="0.794" diaginertia="0.000271946 0.000196219 0.000121103"/>
      <joint name="zarm_r1_joint" pos="0 0 0" axis="0 1 0" range="-2.0933 0.5233" actuatorfrcrange="-60 60"/>
      <geom type="mesh" contype="0" conaffinity="0" group="1" density="0" rgba="1 1 1 1" mesh="r_arm_pitch"/>
      <body name="zarm_r2_link">
        <inertial pos="0.0223009 -0.015695 -0.0202308" quat="0.65931 0.264022 0.580473 0.398313" mass="0.20735" diaginertia="0.000283519 0.000218099 0.000157689"/>
        <joint name="zarm_r2_joint" pos="0 0 0" axis="1 0 0" range="-2.0933 0.3489" actuatorfrcrange="-82.8 82.8"/>
        <geom type="mesh" contype="0" conaffinity="0" group="1" density="0" rgba="1 1 1 1" mesh="r_arm_roll"/>
        <body name="zarm_r3_link">
          <inertial pos="-4.82749e-05 -0.00525815 -0.128822" quat="-0.237177 0.666147 -0.237126 0.666158" mass="1.12063" diaginertia="9.38963e-05 7.96873e-05 7.00576e-05"/>
          <joint name="zarm_r3_joint" pos="0 0 0" axis="0 0 1" range="-1.57 1.57" actuatorfrcrange="-60 60"/>
          <geom type="mesh" contype="0" conaffinity="0" group="1" density="0" rgba="1 1 1 1" mesh="r_arm_yaw"/>
          <body name="zarm_r4_link" pos="0 0 -0.1636">
            <inertial pos="-0.000127233 -0.00951603 -0.0522688" quat="0.314696 0.632501 0.314725 0.633922" mass="0.395825" diaginertia="0.000133455 0.000113904 9.55807e-05"/>
            <joint name="zarm_r4_joint" pos="0 0 0" axis="0 1 0" range="-2.0933 0" actuatorfrcrange="-60 60"/>
            <geom type="mesh" contype="0" conaffinity="0" group="1" density="0" rgba="1 1 1 1" mesh="r_forearm_pitch"/>
            <body name="zarm_r5_link" pos="0 0 -0.19105">
              <inertial pos="-0.000113133 -0.00974484 0.0817961" quat="0.506908 0.493085 0.507703 0.492087" mass="0.380792" diaginertia="0.000122264 8.44608e-05 7.64924e-05"/>
              <joint name="zarm_r5_joint" pos="0 0 0" axis="0 0 1" range="-1.657 1.657" actuatorfrcrange="-6 6"/>
              <geom type="mesh" contype="0" conaffinity="0" group="1" density="0" rgba="1 1 1 1" mesh="r_hand_yaw"/>
              <body name="zarm_r6_link">
                <inertial pos="0.00735987 -0.00475238 0.00605888" quat="0.97227 0.205866 -0.0962427 -0.0552063" mass="0.376651" diaginertia="4.89785e-05 3.6108e-05 2.20226e-05"/>
                <joint name="zarm_r6_joint" pos="0 0 0" axis="0 1 0" range="-1.657 1.657" actuatorfrcrange="-6 6"/>
                <geom type="mesh" contype="0" conaffinity="0" group="1" density="0" rgba="1 1 1 1" mesh="r_hand_pitch"/>
                <body name="zarm_r7_link">
                  <inertial pos="0.00459104 -0.00584264 -0.0836966" quat="0.678609 0.268346 0.578196 0.364925" mass="0.705193" diaginertia="0.000247322 0.000207835 0.000163356"/>
                  <joint name="zarm_r7_joint" pos="0 0 0" axis="1 0 0" range="-1.57 1.57" actuatorfrcrange="-6 6"/>
                  <geom type="mesh" contype="0" conaffinity="0" group="1" density="0" rgba="1 1 1 1" mesh="r_hand_roll"/>
                  <geom size="0.005" pos="0 0.03 -0.17"/>
                  <body name="r_thumb_proximal_yaw" pos="0.0240163 0.0216278 -0.1107">
                    <inertial pos="0.00590167 0.00373751 0.000280878" quat="0.296079 0.363683 0.600132 0.648007" mass="0.00177458" diaginertia="1.00106e-07 9.8657e-08 3.43995e-08"/>
                    <joint name="r_thumb_proximal_yaw_joint" pos="0 0 0" axis="0 0 1"/>
                    <geom type="mesh" contype="0" conaffinity="0" group="1" density="0" rgba="1 1 1 0.25" mesh="r_thumb_proximal_yaw"/>
                    <geom type="mesh" rgba="1 1 1 0.25" mesh="r_thumb_proximal_yaw"/>
                    <body name="r_thumb_distal_pitch" pos="0.012 0.0065 0.0004">
                      <inertial pos="0.00835401 -1.55022e-06 -0.0372052" quat="0.999868 -1.94096e-06 0.0162762 -0.000119236" mass="0.0143595" diaginertia="7.16051e-06 6.87911e-06 9.08132e-07"/>
                      <joint name="r_thumb_distal_pitch_joint" pos="0 0 0" axis="0 -1 0"/>
                      <geom type="mesh" contype="0" conaffinity="0" group="1" density="0" rgba="1 1 1 1" mesh="r_thumb_distal_pitch"/>
                      <geom type="mesh" rgba="1 1 1 1" mesh="r_thumb_distal_pitch"/>
                    </body>
                  </body>
                  <body name="r_index_proximal_finger" pos="0.0285188 -0.00394879 -0.174731" quat="0.999879 0 -0.0155832 0">
                    <inertial pos="0.00011763 -0.00210444 -0.0171028" quat="0.685653 -0.055689 0.0524965 0.723894" mass="0.00213738" diaginertia="3.47927e-07 3.18535e-07 9.08146e-08"/>
                    <joint name="r_index_proximal_finger_joint" pos="0 0 0" axis="0.998506 0.0546396 0"/>
                    <geom type="mesh" contype="0" conaffinity="0" group="1" density="0" rgba="1 1 1 1" mesh="r_index_proximal_finger"/>
                    <geom type="mesh" rgba="1 1 1 1" mesh="r_index_proximal_finger"/>
                    <body name="r_index_distal_finger" pos="0.000133519 -0.00243999 -0.0349146">
                      <inertial pos="-8.92322e-05 0.00161947 -0.0254573" quat="0.687696 0.0176182 -0.0166735 0.725594" mass="0.00504466" diaginertia="7.81732e-07 7.63452e-07 1.13799e-07"/>
                      <joint name="r_index_distal_finger_joint" pos="0 0 0" axis="-0.998506 -0.0546396 0"/>
                      <geom type="mesh" contype="0" conaffinity="0" group="1" density="0" rgba="1 1 1 1" mesh="r_index_distal_finger"/>
                      <geom type="mesh" rgba="1 1 1 1" mesh="r_index_distal_finger"/>
                    </body>
                  </body>
                  <body name="r_middle_proximal_finger" pos="0.00751626 -0.00820382 -0.178435">
                    <inertial pos="8.44814e-08 -0.0027021 -0.020783" quat="0.705466 -0.0478411 0.0478411 0.705507" mass="0.00260456" diaginertia="5.44468e-07 5.09608e-07 1.18037e-07"/>
                    <joint name="r_middle_proximal_finger_joint" pos="0 0 0" axis="1 0 0"/>
                    <geom type="mesh" contype="0" conaffinity="0" group="1" density="0" rgba="1 1 1 1" mesh="r_middle_proximal_finger"/>
                    <geom type="mesh" rgba="1 1 1 1" mesh="r_middle_proximal_finger"/>
                    <body name="r_middle_distal_finger" pos="0 -0.00292977 -0.0418977">
                      <inertial pos="-6.04521e-07 0.00162351 -0.0254572" quat="0.707266 0.0171778 -0.0171703 0.70653" mass="0.00504467" diaginertia="7.81735e-07 7.63455e-07 1.13799e-07"/>
                      <joint name="r_middle_distal_finger_joint" pos="0 0 0" axis="-1 0 0"/>
                      <geom type="mesh" contype="0" conaffinity="0" group="1" density="0" rgba="1 1 1 1" mesh="r_middle_distal_finger"/>
                      <geom type="mesh" rgba="1 1 1 1" mesh="r_middle_distal_finger"/>
                    </body>
                  </body>
                  <body name="r_ring_proximal_finger" pos="-0.0135863 -0.00807856 -0.176447" quat="0.999879 0 0.0155832 0">
                    <inertial pos="-0.000147628 -0.00269936 -0.0207828" quat="0.724482 -0.0465377 0.0491525 0.685962" mass="0.00260456" diaginertia="5.44468e-07 5.09608e-07 1.18037e-07"/>
                    <joint name="r_ring_proximal_finger_joint" pos="0 0 0" axis="0.998506 -0.0546396 0"/>
                    <geom type="mesh" contype="0" conaffinity="0" group="1" density="0" rgba="1 1 1 1" mesh="r_ring_proximal_finger"/>
                    <geom type="mesh" rgba="1 1 1 1" mesh="r_ring_proximal_finger"/>
                    <body name="r_ring_distal_finger" pos="-0.000160223 -0.00292799 -0.0418975">
                      <inertial pos="-3.05447e-05 -0.00055183 -0.0145819" quat="0.726055 0.00927821 -0.00980929 0.687504" mass="0.00182869" diaginertia="2.76147e-07 2.63473e-07 4.68174e-08"/>
                      <joint name="r_ring_distal_finger_joint" pos="0 0 0" axis="-0.996567 -0.0546396 -0.0622018"/>
                      <geom type="mesh" contype="0" conaffinity="0" group="1" density="0" rgba="1 1 1 1" mesh="r_ring_distal_finger"/>
                      <geom type="mesh" rgba="1 1 1 1" mesh="r_ring_distal_finger"/>
                    </body>
                  </body>
                  <body name="r_pinky_proximal_finger" pos="-0.0342147 -0.00363387 -0.170227" quat="0.999456 0 0.0329919 0">
                    <inertial pos="-0.000117693 -0.00210238 -0.0171031" quat="0.725022 -0.0526316 0.05548 0.684467" mass="0.00213737" diaginertia="3.47927e-07 3.18535e-07 9.08141e-08"/>
                    <joint name="r_pinky_proximal_finger_joint" pos="0 0 0" axis="0.99837 -0.0570678 0"/>
                    <geom type="mesh" contype="0" conaffinity="0" group="1" density="0" rgba="1 1 1 1" mesh="r_pinky_proximal_finger"/>
                    <geom type="mesh" rgba="1 1 1 1" mesh="r_pinky_proximal_finger"/>
                    <body name="r_pinky_distal_finger" pos="-0.000139217 -0.00243553 -0.0349149">
                      <inertial pos="-6.68864e-05 -0.000791925 -0.0127151" quat="0.727312 0.00425992 -0.00197281 0.686291" mass="0.00162994" diaginertia="1.94746e-07 1.83818e-07 3.94541e-08"/>
                      <joint name="r_pinky_distal_finger_joint" pos="0 0 0" axis="-0.99837 0.0570678 0"/>
                      <geom type="mesh" contype="0" conaffinity="0" group="1" density="0" rgba="1 1 1 1" mesh="r_pinky_distal_finger"/>
                      <geom type="mesh" rgba="1 1 1 1" mesh="r_pinky_distal_finger"/>
                    </body>
                  </body>
                </body>
              </body>
            </body>
          </body>
        </body>
      </body>
    </body>
  </worldbody>

  <actuator>
        <motor gear="1" joint="leg_l1_joint" name="leg_l1_motor" ctrllimited="true"  ctrlrange='-150 150'/>
        <motor gear="1" joint="leg_l2_joint" name="leg_l2_motor" ctrllimited="true"  ctrlrange='-150 150'/>
        <motor gear="1" joint="leg_l3_joint" name="leg_l3_motor" ctrllimited="true"  ctrlrange='-200 200'/>
        <motor gear="1" joint="leg_l4_joint" name="leg_l4_motor" ctrllimited="true"  ctrlrange='-200 200'/>
        <motor gear="1" joint="leg_l5_joint" name="leg_l5_motor" ctrllimited="true"  ctrlrange='-90 90'/>
        <motor gear="1" joint="leg_l6_joint" name="leg_l6_motor" ctrllimited="true"  ctrlrange='-90 90'/>

        <motor gear="1" joint="leg_r1_joint" name="leg_r1_motor" ctrllimited="true"  ctrlrange='-150 150'/>
        <motor gear="1" joint="leg_r2_joint" name="leg_r2_motor" ctrllimited="true"  ctrlrange='-150 150'/>
        <motor gear="1" joint="leg_r3_joint" name="leg_r3_motor" ctrllimited="true"  ctrlrange='-200 200'/>
        <motor gear="1" joint="leg_r4_joint" name="leg_r4_motor" ctrllimited="true"  ctrlrange='-200 200'/>
        <motor gear="1" joint="leg_r5_joint" name="leg_r5_motor" ctrllimited="true"  ctrlrange='-90 90'/>
        <motor gear="1" joint="leg_r6_joint" name="leg_r6_motor" ctrllimited="true"  ctrlrange='-90 90'/>

        <motor gear="1" joint="zarm_l1_joint" name="zarm_l1_motor" ctrllimited="true"  ctrlrange='-150 150'/>
        <motor gear="1" joint="zarm_l2_joint" name="zarm_l2_motor" ctrllimited="true"  ctrlrange='-150 150'/>
        <motor gear="1" joint="zarm_l3_joint" name="zarm_l3_motor" ctrllimited="true"  ctrlrange='-200 200'/>
        <motor gear="1" joint="zarm_l4_joint" name="zarm_l4_motor" ctrllimited="true"  ctrlrange='-200 200'/>
        <motor gear="1" joint="zarm_l5_joint" name="zarm_l5_motor" ctrllimited="true"  ctrlrange='-90 90'/>
        <motor gear="1" joint="zarm_l6_joint" name="zarm_l6_motor" ctrllimited="true"  ctrlrange='-90 90'/>
        <motor gear="1" joint="zarm_l7_joint" name="zarm_l7_motor" ctrllimited="true"  ctrlrange='-90 90'/>

        <motor gear="1" joint="zarm_r1_joint" name="zarm_r1_motor" ctrllimited="true"  ctrlrange='-150 150'/>
        <motor gear="1" joint="zarm_r2_joint" name="zarm_r2_motor" ctrllimited="true"  ctrlrange='-150 150'/>
        <motor gear="1" joint="zarm_r3_joint" name="zarm_r3_motor" ctrllimited="true"  ctrlrange='-200 200'/>
        <motor gear="1" joint="zarm_r4_joint" name="zarm_r4_motor" ctrllimited="true"  ctrlrange='-200 200'/>
        <motor gear="1" joint="zarm_r5_joint" name="zarm_r5_motor" ctrllimited="true"  ctrlrange='-90 90'/>
        <motor gear="1" joint="zarm_r6_joint" name="zarm_r6_motor" ctrllimited="true"  ctrlrange='-90 90'/>
        <motor gear="1" joint="zarm_r7_joint" name="zarm_r7_motor" ctrllimited="true"  ctrlrange='-90 90'/>


        <motor gear="1" joint="l_thumb_proximal_yaw_joint"     name="l_thumb_proximal_yaw_motor"     ctrllimited="true"  ctrlrange='-90 90'/>         
        <motor gear="1" joint="l_thumb_distal_pitch_joint"     name="l_thumb_distal_pitch_motor"     ctrllimited="true"  ctrlrange='-90 90'/>          
        <motor gear="1" joint="l_index_proximal_finger_joint"  name="l_index_proximal_finger_motor"  ctrllimited="true"  ctrlrange='-90 90'/>          
        <motor gear="1" joint="l_index_distal_finger_joint"    name="l_index_distal_finger_motor"    ctrllimited="true"  ctrlrange='-90 90'/>             
        <motor gear="1" joint="l_middle_proximal_finger_joint" name="l_middle_proximal_finger_motor" ctrllimited="true"  ctrlrange='-90 90'/>         
        <motor gear="1" joint="l_middle_distal_finger_joint"   name="l_middle_distal_finger_motor"   ctrllimited="true"  ctrlrange='-90 90'/>          
        <motor gear="1" joint="l_ring_proximal_finger_joint"   name="l_ring_proximal_finger_motor"   ctrllimited="true"  ctrlrange='-90 90'/>            
        <motor gear="1" joint="l_ring_distal_finger_joint"     name="l_ring_distal_finger_motor"     ctrllimited="true"  ctrlrange='-90 90'/>              
        <motor gear="1" joint="l_pinky_proximal_finger_joint"  name="l_pinky_proximal_finger_motor"  ctrllimited="true"  ctrlrange='-90 90'/>            
        <motor gear="1" joint="l_pinky_distal_finger_joint"    name="l_pinky_distal_finger_motor"    ctrllimited="true"  ctrlrange='-90 90'/>   

        <motor gear="1" joint="r_thumb_proximal_yaw_joint"     name="r_thumb_proximal_yaw_motor"     ctrllimited="true"  ctrlrange='-90 90'/>               
        <motor gear="1" joint="r_thumb_distal_pitch_joint"     name="r_thumb_distal_pitch_motor"     ctrllimited="true"  ctrlrange='-90 90'/>                  
        <motor gear="1" joint="r_index_proximal_finger_joint"  name="r_index_proximal_finger_motor"  ctrllimited="true"  ctrlrange='-90 90'/>              
        <motor gear="1" joint="r_index_distal_finger_joint"    name="r_index_distal_finger_motor"    ctrllimited="true"  ctrlrange='-90 90'/>               
        <motor gear="1" joint="r_middle_proximal_finger_joint" name="r_middle_proximal_finger_motor" ctrllimited="true"  ctrlrange='-90 90'/>              
        <motor gear="1" joint="r_middle_distal_finger_joint"   name="r_middle_distal_finger_motor"   ctrllimited="true"  ctrlrange='-90 90'/>          
        <motor gear="1" joint="r_ring_proximal_finger_joint"   name="r_ring_proximal_finger_motor"   ctrllimited="true"  ctrlrange='-90 90'/>                
        <motor gear="1" joint="r_ring_distal_finger_joint"     name="r_ring_distal_finger_motor"     ctrllimited="true"  ctrlrange='-90 90'/>         
        <motor gear="1" joint="r_pinky_proximal_finger_joint"  name="r_pinky_proximal_finger_motor"  ctrllimited="true"  ctrlrange='-90 90'/>              
        <motor gear="1" joint="r_pinky_distal_finger_joint"    name="r_pinky_distal_finger_motor"    ctrllimited="true"  ctrlrange='-90 90'/>            
  </actuator>
  <sensor>
      <accelerometer name="BodyAcc" site="imu"/>
      <velocimeter name="BodyVel" site="imu"/>
      <gyro name="BodyGyro" site="imu"/>
      <framepos name="BodyPos" objtype="site" objname="imu"/>
      <framequat name="BodyQuat" objtype="site" objname="imu"/>

      <jointpos name="leg_l1_pos" joint="leg_l1_joint"/>
      <jointpos name="leg_l2_pos" joint="leg_l2_joint"/>
      <jointpos name="leg_l3_pos" joint="leg_l3_joint"/>
      <jointpos name="leg_l4_pos" joint="leg_l4_joint"/>
      <jointpos name="leg_l5_pos" joint="leg_l5_joint"/>
      <jointpos name="leg_l6_pos" joint="leg_l6_joint"/>

      <jointpos name="leg_r1_pos" joint="leg_r1_joint"/>
      <jointpos name="leg_r2_pos" joint="leg_r2_joint"/>
      <jointpos name="leg_r3_pos" joint="leg_r3_joint"/>
      <jointpos name="leg_r4_pos" joint="leg_r4_joint"/>
      <jointpos name="leg_r5_pos" joint="leg_r5_joint"/>
      <jointpos name="leg_r6_pos" joint="leg_r6_joint"/>

      <jointpos name="zarm_l1_pos" joint="zarm_l1_joint"/>
      <jointpos name="zarm_l2_pos" joint="zarm_l2_joint"/>
      <jointpos name="zarm_l3_pos" joint="zarm_l3_joint"/>
      <jointpos name="zarm_l4_pos" joint="zarm_l4_joint"/>
      <jointpos name="zarm_l5_pos" joint="zarm_l5_joint"/>
      <jointpos name="zarm_l6_pos" joint="zarm_l6_joint"/>
      <jointpos name="zarm_l7_pos" joint="zarm_l7_joint"/>

      <jointpos name="zarm_r1_pos" joint="zarm_r1_joint"/>
      <jointpos name="zarm_r2_pos" joint="zarm_r2_joint"/>
      <jointpos name="zarm_r3_pos" joint="zarm_r3_joint"/>
      <jointpos name="zarm_r4_pos" joint="zarm_r4_joint"/>
      <jointpos name="zarm_r5_pos" joint="zarm_r5_joint"/>
      <jointpos name="zarm_r6_pos" joint="zarm_r6_joint"/>
      <jointpos name="zarm_r7_pos" joint="zarm_r7_joint"/>

      <jointpos name="l_thumb_proximal_yaw_pos"      joint="l_thumb_proximal_yaw_joint"      />         
      <jointpos name="l_thumb_distal_pitch_pos"      joint="l_thumb_distal_pitch_joint"      />          
      <jointpos name="l_index_proximal_finger_pos"   joint="l_index_proximal_finger_joint"   />          
      <jointpos name="l_index_distal_finger_pos"     joint="l_index_distal_finger_joint"     />             
      <jointpos name="l_middle_proximal_finger_pos"  joint="l_middle_proximal_finger_joint"  />         
      <jointpos name="l_middle_distal_finger_pos"    joint="l_middle_distal_finger_joint"    />          
      <jointpos name="l_ring_proximal_finger_pos"    joint="l_ring_proximal_finger_joint"    />            
      <jointpos name="l_ring_distal_finger_pos"      joint="l_ring_distal_finger_joint"      />              
      <jointpos name="l_pinky_proximal_finger_pos"   joint="l_pinky_proximal_finger_joint"   />            
      <jointpos name="l_pinky_distal_finger_pos"     joint="l_pinky_distal_finger_joint"     />   
              
      <jointpos name="r_thumb_proximal_yaw_pos"      joint="r_thumb_proximal_yaw_joint"      />               
      <jointpos name="r_thumb_distal_pitch_pos"      joint="r_thumb_distal_pitch_joint"      />                  
      <jointpos name="r_index_proximal_finger_pos"   joint="r_index_proximal_finger_joint"   />              
      <jointpos name="r_index_distal_finger_pos"     joint="r_index_distal_finger_joint"     />               
      <jointpos name="r_middle_proximal_finger_pos"  joint="r_middle_proximal_finger_joint"  />              
      <jointpos name="r_middle_distal_finger_pos"    joint="r_middle_distal_finger_joint"    />          
      <jointpos name="r_ring_proximal_finger_pos"    joint="r_ring_proximal_finger_joint"    />                
      <jointpos name="r_ring_distal_finger_pos"      joint="r_ring_distal_finger_joint"      />         
      <jointpos name="r_pinky_proximal_finger_pos"   joint="r_pinky_proximal_finger_joint"   />              
      <jointpos name="r_pinky_distal_finger_pos"     joint="r_pinky_distal_finger_joint"     />  

      <jointvel name="leg_l1_vel" joint="leg_l1_joint"/>
      <jointvel name="leg_l2_vel" joint="leg_l2_joint"/>
      <jointvel name="leg_l3_vel" joint="leg_l3_joint"/>
      <jointvel name="leg_l4_vel" joint="leg_l4_joint"/>
      <jointvel name="leg_l5_vel" joint="leg_l5_joint"/>
      <jointvel name="leg_l6_vel" joint="leg_l6_joint"/>

      <jointvel name="leg_r1_vel" joint="leg_r1_joint"/>
      <jointvel name="leg_r2_vel" joint="leg_r2_joint"/>
      <jointvel name="leg_r3_vel" joint="leg_r3_joint"/>
      <jointvel name="leg_r4_vel" joint="leg_r4_joint"/>
      <jointvel name="leg_r5_vel" joint="leg_r5_joint"/>
      <jointvel name="leg_r6_vel" joint="leg_r6_joint"/>

      <jointvel name="zarm_l1_vel" joint="zarm_l1_joint"/>
      <jointvel name="zarm_l2_vel" joint="zarm_l2_joint"/>
      <jointvel name="zarm_l3_vel" joint="zarm_l3_joint"/>
      <jointvel name="zarm_l4_vel" joint="zarm_l4_joint"/>
      <jointvel name="zarm_l5_vel" joint="zarm_l5_joint"/>
      <jointvel name="zarm_l6_vel" joint="zarm_l6_joint"/>
      <jointvel name="zarm_l7_vel" joint="zarm_l7_joint"/>

      <jointvel name="zarm_r1_vel" joint="zarm_r1_joint"/>
      <jointvel name="zarm_r2_vel" joint="zarm_r2_joint"/>
      <jointvel name="zarm_r3_vel" joint="zarm_r3_joint"/>
      <jointvel name="zarm_r4_vel" joint="zarm_r4_joint"/>
      <jointvel name="zarm_r5_vel" joint="zarm_r5_joint"/>
      <jointvel name="zarm_r6_vel" joint="zarm_r6_joint"/>
      <jointvel name="zarm_r7_vel" joint="zarm_r7_joint"/>

      <jointvel name="l_thumb_proximal_yaw_vel"      joint="l_thumb_proximal_yaw_joint"      />         
      <jointvel name="l_thumb_distal_pitch_vel"      joint="l_thumb_distal_pitch_joint"      />          
      <jointvel name="l_index_proximal_finger_vel"   joint="l_index_proximal_finger_joint"   />          
      <jointvel name="l_index_distal_finger_vel"     joint="l_index_distal_finger_joint"     />             
      <jointvel name="l_middle_proximal_finger_vel"  joint="l_middle_proximal_finger_joint"  />         
      <jointvel name="l_middle_distal_finger_vel"    joint="l_middle_distal_finger_joint"    />          
      <jointvel name="l_ring_proximal_finger_vel"    joint="l_ring_proximal_finger_joint"    />            
      <jointvel name="l_ring_distal_finger_vel"      joint="l_ring_distal_finger_joint"      />              
      <jointvel name="l_pinky_proximal_finger_vel"   joint="l_pinky_proximal_finger_joint"   />            
      <jointvel name="l_pinky_distal_finger_vel"     joint="l_pinky_distal_finger_joint"     />   
      
      <jointvel name="r_thumb_proximal_yaw_vel"      joint="r_thumb_proximal_yaw_joint"      />               
      <jointvel name="r_thumb_distal_pitch_vel"      joint="r_thumb_distal_pitch_joint"      />                  
      <jointvel name="r_index_proximal_finger_vel"   joint="r_index_proximal_finger_joint"   />              
      <jointvel name="r_index_distal_finger_vel"     joint="r_index_distal_finger_joint"     />               
      <jointvel name="r_middle_proximal_finger_vel"  joint="r_middle_proximal_finger_joint"  />              
      <jointvel name="r_middle_distal_finger_vel"    joint="r_middle_distal_finger_joint"    />          
      <jointvel name="r_ring_proximal_finger_vel"    joint="r_ring_proximal_finger_joint"    />                
      <jointvel name="r_ring_distal_finger_vel"      joint="r_ring_distal_finger_joint"      />         
      <jointvel name="r_pinky_proximal_finger_vel"   joint="r_pinky_proximal_finger_joint"   />              
      <jointvel name="r_pinky_distal_finger_vel"     joint="r_pinky_distal_finger_joint"     />  

  </sensor>  

</mujoco>
