<?xml version="1.0" encoding="utf-8"?>
<!-- This URDF was automatically created by SolidWorks to URDF Exporter! Originally created by
Stephen Brawner (brawner@gmail.com) 
     Commit Version: 1.6.0-4-g7f85cfe  Build Version: 1.6.7995.38578
     For more information, please see http://wiki.ros.org/sw_urdf_exporter -->
<robot name="biped_s4">
  <mujoco>
    <compiler meshdir="../meshes/" balanceinertia="true" discardvisual="false"/>
  </mujoco>
  <!-- <link name="dummy_link">
  </link> -->
  <link name="base_link">
    <inertial>
      <origin 
        xyz="-0.0 0.0 0.12722577"
      	rpy="0 0 0" />
      <mass 
        value="22.46493"  />
      <inertia 
        ixx="0.62588371"
        ixy="-0.00011772"
        ixz="0.01585114"
        iyy="0.56247677"
        iyz="0.00086199"
        izz="0.20014604"  />
    </inertial>
    <visual>
      <origin 
        xyz="0 0 0"
        rpy="0 0 0" />
      <geometry>
        <mesh filename="package://biped_s40_hand/meshes/torso.obj" />
      </geometry>
      <material 
        name="">
        <color 
          rgba="1 1 1 1" />
      </material>
    </visual>
  </link>
  <!-- <joint name="dummy_to_base_link" type="fixed">
    <parent link="dummy_link"/>
    <child link="base_link"/>
    <origin rpy="0 0 0" xyz="0 0 0"/>
  </joint> -->

  <link name="base_camera">
      <visual>
          <origin 
              xyz="0 0 0" 
              rpy="0 0 0" />
          <geometry>
              <sphere radius="0.001"/>
          </geometry>
          <material 
              name="">
              <color 
                  rgba="1 1 1 1" />
          </material>
      </visual>
  </link>
  <joint name="base_camera" type="fixed">
      <origin xyz="0.11416 0.0175 0.28459" rpy="0 0.71522222 0" />
      <parent link="base_link" />
      <child link="base_camera" />
  </joint>

  <!-- ************************************************************ -->
  <!-- *********************** Left leg *************************** -->
  <!-- ************************************************************ -->

  <link name="leg_l1_link">
    <inertial>
      <origin 
        xyz="0.06614234 -0.00000119 -0.00862806"
        rpy="0 0 0" />
      <mass 
        value="1.53800733"
      />
      <inertia 
        ixx="0.00189451"
        ixy="-0.00000100"
        ixz="-0.00010566"
        iyy="0.00282649"
        iyz="-0.00000006"
        izz="0.00366404" />
    </inertial>
    <visual>
      <origin 
        xyz="0 0 0"
        rpy="0 0 0" />
      <geometry>
        <mesh filename="package://biped_s40_hand/meshes/l_leg_roll.obj" />
      </geometry>
      <material 
        name="">
        <color 
          rgba="0.6902 0.65882 0.63922 1" />
      </material>
    </visual>
  </link>
  <joint 
    name="leg_l1_joint"
    type="revolute">
    <origin 
      xyz="-0.139 0.088087 -0.065549"
      rpy="0 0 0" />
    <parent 
      link="base_link" />
    <child 
      link="leg_l1_link" />
    <axis 
      xyz="1 0 0" />
    <limit
      lower="-0.31"
      upper="0.66"
      effort="85"
      velocity="14" />
  </joint>

  <link 
    name="leg_l2_link">
    <inertial>
      <origin 
        xyz="0.00000000 0.04610400 -0.13256100"
        rpy="0 0 0" />
      <mass 
        value="1.60096700"/>
      <inertia 
        ixx="0.00698359"
        ixy="0.00000237"
        ixz="-0.00000315"
        iyy="0.00460736"
        iyz="-0.00105143"
        izz="0.00482586" />
    </inertial>
    <visual>
      <origin 
        xyz="0 0 0"
        rpy="0 0 0" />
      <geometry>
        <mesh filename="package://biped_s40_hand/meshes/l_leg_yaw.obj" />
      </geometry>
      <material 
        name="">
        <color rgba="0.65098 0.61961 0.58824 1" />
      </material>
    </visual>
  </link>
  <joint name="leg_l2_joint"
    type="revolute">
    <origin 
      xyz="0.1365 -0.0010866 -0.033901"
      rpy="0 0 0" />
    <parent 
      link="leg_l1_link" />
    <child 
      link="leg_l2_link" />
    <axis 
      xyz="0 0 1" />
    <limit
      lower="-0.52"
      upper="1.04"
      effort="60"
      velocity="14" />
  </joint>

  <link name="leg_l3_link">
    <inertial>
      <origin 
        xyz="-0.00644903 -0.09813560 -0.05357606"
        rpy="0 0 0" />
      <mass 
        value="2.46657100"/>
      <inertia 
        ixx="0.02261778"
        ixy="-0.00007906"
        ixz="-0.00029350"
        iyy="0.02315672"
        iyz="-0.00182962"
        izz="0.00415881" />
    </inertial>
    <visual>
      <origin 
        xyz="0 0 0"
        rpy="0 0 0" />
      <geometry>
        <mesh 
          filename="package://biped_s40_hand/meshes/l_leg_pitch.obj" />
      </geometry>
      <material 
        name="">
        <color 
          rgba="0.52941 0.54902 0.54902 1" />
      </material>
    </visual>
  </link>
  <joint 
    name="leg_l3_joint"
    type="revolute">
    <origin 
      xyz="0 0.094 -0.09"
      rpy="0 0 0" />
    <parent 
      link="leg_l2_link" />
    <child 
      link="leg_l3_link" />
    <axis 
      xyz="0 1 0" />
    <limit
      lower="-1.83"
      upper="1.04"
      effort="85"
      velocity="14" />
  </joint>

  <link name="leg_l4_link">
    <inertial>
      <origin 
        xyz="0.00080045 -0.00004225 -0.12049699"
        rpy="0 0 0" />
      <mass 
        value="1.62911554" />
      <inertia 
        ixx="0.01343597"
        ixy="-0.00000234"
        ixz="0.00020391"
        iyy="0.01359234"
        iyz="0.00018311"
        izz="0.00092149" />
    </inertial>
    <visual>
      <origin 
        xyz="0 0 0"
        rpy="0 0 0" />
      <geometry>
        <mesh 
          filename="package://biped_s40_hand/meshes/l_knee.obj" />
      </geometry>
      <material 
        name="">
        <color rgba="0.68627 0.65882 0.63922 1" />
      </material>
    </visual>
  </link>
  <joint name="leg_l4_joint"
    type="revolute">
    <origin 
      xyz="0.004136 -0.06635 -0.24997"
      rpy="0 0 0" />
    <parent 
      link="leg_l3_link" />
    <child 
      link="leg_l4_link" />
    <axis 
      xyz="0 1 0" />
    <limit
      lower="-0.0"
      upper="2.18"
      effort="85"
      velocity="14" />
  </joint>

  <link name="leg_l5_link">
    <inertial>
      <origin 
        xyz="0.00000000 -0.02099982 0"
        rpy="0 0 0" />
      <mass 
        value="0.05444454" />
      <inertia 
        ixx="0.00000411"
        ixy="0.00000000"
        ixz="0.00000000"
        iyy="0.00000411"
        iyz="0.00000000"
        izz="0.00000728" />
    </inertial>
    <visual>
      <origin 
        xyz="0 0 0"
        rpy="0 0 0" />
      <geometry>
        <mesh filename="package://biped_s40_hand/meshes/l_foot_pitch.obj" />
      </geometry>
      <material name="">
        <color rgba="0.6902 0.65882 0.63922 1" />
      </material>
    </visual>
  </link>
  <joint 
    name="leg_l5_joint"
    type="revolute">
    <origin 
      xyz="0 -0.0022 -0.346"
      rpy="0 0 0" />
    <parent 
      link="leg_l4_link" />
    <child 
      link="leg_l5_link" />
    <axis 
      xyz="0 1 0" />
    <limit
      lower="-0.61"
      upper="0.52"
      effort="36"
      velocity="14" />
  </joint>

  <link name="leg_l6_link">
    <inertial>
      <origin 
        xyz="-0.03594832 0.00000978 -0.02713029"
        rpy="0 0 0" />
      <mass 
        value="0.46707519" />
      <inertia 
        ixx="0.00040711"
        ixy="0.00000016"
        ixz="-0.00023147"
        iyy="0.00127525"
        iyz="-0.00000006"
        izz="0.00135360" />
    </inertial>
    <visual>
      <origin 
        xyz="0 0 0"
        rpy="0 0 0" />
      <geometry>
        <mesh filename="package://biped_s40_hand/meshes/l_foot_roll.obj" />
      </geometry>
      <material 
        name="">
        <color 
          rgba="0.6902 0.65882 0.63922 1" />
      </material>
    </visual>
    <visual>
      <origin rpy="0 0 0" xyz="-0.09 0.05 -0.0465" />
      <geometry>
        <sphere radius="0.005" />
      </geometry>
    </visual>
    <collision>
      <origin rpy="0 0 0" xyz="-0.09 0.05 -0.0465" />
      <geometry>
        <sphere radius="0.005" />
      </geometry>
    </collision>
    <visual>
      <origin rpy="0 0 0" xyz="-0.09 -0.05 -0.0465" />
      <geometry>
        <sphere radius="0.005" />
      </geometry>
    </visual>
    <collision>
      <origin rpy="0 0 0" xyz="-0.09 -0.05 -0.0465" />
      <geometry>
        <sphere radius="0.005" />
      </geometry>
    </collision>
    <visual>
      <origin rpy="0 0 0" xyz="0.15 0.05 -0.0465" />
      <geometry>
        <sphere radius="0.005" />
      </geometry>
    </visual>
    <collision>
      <origin rpy="0 0 0" xyz="0.15 0.05 -0.0465" />
      <geometry>
        <sphere radius="0.005" />
      </geometry>
    </collision>
    <visual>
      <origin rpy="0 0 0" xyz="0.15 -0.05 -0.0465" />
      <geometry>
        <sphere radius="0.005" />
      </geometry>
    </visual>
    <collision>
      <origin rpy="0 0 0" xyz="0.15 -0.05 -0.0465" />
      <geometry>
        <sphere radius="0.005" />
      </geometry>
    </collision>
  </link>
  <joint 
    name="leg_l6_joint"
    type="revolute">
    <origin 
      xyz="0 0 0"
      rpy="0 0 0" />
    <parent 
      link="leg_l5_link" />
    <child 
      link="leg_l6_link" />
    <axis 
      xyz="1 0 0" />
    <limit
      lower="-0.61"
      upper="0.52"
      effort="36"
      velocity="14" />
  </joint>

  <link 
    name="ll_foot_toe">
    <collision>
      <origin 
        rpy="0 0 0"
        xyz="0 0 0"/>
      <geometry>
        <sphere radius="0.005"/>
      </geometry>
    </collision>
  </link>
  <joint name="ll_foot_toe_joint"
    type="fixed">
    <origin 
      xyz="0.15 0.05 -0.0465"
      rpy="0 0 0" />
    <parent 
      link="leg_l6_link" />
    <child 
      link="ll_foot_toe" />
  </joint>
  <link name="ll_foot_heel">
    <collision>
      <origin 
        rpy="0 0 0"
        xyz="0 0 0"/>
      <geometry>
        <sphere radius="0.005"/>
      </geometry>
    </collision>
  </link>
  <joint 
    name="ll_foot_heel_joint"
    type="fixed">
    <origin 
      xyz="-0.09 0.05 -0.0465"
      rpy="0 0 0" />
    <parent link="leg_l6_link" />
    <child link="ll_foot_heel" />
  </joint>

  <link name="lr_foot_toe">
    <collision>
      <origin 
        rpy="0 0 0"
        xyz="0 0 0"/>
      <geometry>
        <sphere radius="0.005"/>
      </geometry>
    </collision>
  </link>
  <joint 
    name="lr_foot_toe_joint"
    type="fixed">
    <origin 
      xyz="0.15 -0.05 -0.0465"
      rpy="0 0 0" />
    <parent 
      link="leg_l6_link" />
    <child 
      link="lr_foot_toe" />
  </joint>
  <link 
    name="lr_foot_heel">
    <collision>
      <origin 
        rpy="0 0 0"
        xyz="0 0 0"/>
      <geometry>
        <sphere radius="0.005"/>
      </geometry>
    </collision>
  </link>
  <joint 
    name="lr_foot_heel_joint"
    type="fixed">
    <origin 
      xyz="-0.09 -0.05 -0.0465"
      rpy="0 0 0" />
    <parent 
      link="leg_l6_link" />
    <child 
      link="lr_foot_heel" />
  </joint>
  <link name="l_foot_toe">
    <collision>
      <origin 
        rpy="0 0 0"
        xyz="0 0 0"/>
      <geometry>
        <sphere radius="0.005"/>
      </geometry>
    </collision>
  </link>
  <joint 
    name="l_foot_toe_joint"
    type="fixed">
    <origin 
      xyz="0.15 0.0 -0.0465"
      rpy="0 0 0" />
    <parent 
      link="leg_l6_link" />
    <child 
      link="l_foot_toe" />
  </joint>
  <link name="l_foot_heel">
    <collision>
      <origin 
        rpy="0 0 0"
        xyz="0 0 0"/>
      <geometry>
        <sphere radius="0.005"/>
      </geometry>
    </collision>
  </link>
  <joint 
    name="l_foot_heel_joint"
    type="fixed">
    <origin xyz="-0.09 0.0 -0.0465"
      rpy="0 0 0" />
    <parent 
      link="leg_l6_link" />
    <child 
      link="l_foot_heel" />
  </joint>

  <!-- ************************************************************ -->
  <!-- ********************** Right leg *************************** -->
  <!-- ************************************************************ -->
  <link 
    name="leg_r1_link">
    <inertial>
      <origin 
        xyz="0.06614233 0.00000119 -0.00862806"
        rpy="0 0 0" />
      <mass 
        value="1.53800714" />
      <inertia 
        ixx="0.00189451"
        ixy="0.00000100"
        ixz="-0.00010566"
        iyy="0.00282648"
        iyz="0.00000006"
        izz="0.00366404" />
    </inertial>
    <visual>
      <origin 
        xyz="0 0 0"
        rpy="0 0 0" />
      <geometry>
        <mesh filename="package://biped_s40_hand/meshes/r_leg_roll.obj" />
      </geometry>
      <material 
        name="">
        <color rgba="0.6902 0.65882 0.63922 1" />
      </material>
    </visual>
  </link>
  <joint name="leg_r1_joint"
    type="revolute">
    <origin 
      xyz="-0.139 -0.088087 -0.065549"
      rpy="0 0 0" />
    <parent 
      link="base_link" />
    <child 
      link="leg_r1_link" />
    <axis 
      xyz="1 0 0" />
    <limit
      lower="-0.6629"
      upper="0.314"
      effort="85"
      velocity="14" />
  </joint>

  <link name="leg_r2_link">
    <inertial>
      <origin 
        xyz="0.00004661 -0.04610359 -0.13257364"
        rpy="0 0 0" />
      <mass 
        value="1.60096695" />
      <inertia 
        ixx="0.00520439"
        ixy="-0.00000302"
        ixz="-0.00000372"
        iyy="0.00397740"
        iyz="0.00063198"
        izz="0.00391648" />
    </inertial>
    <visual>
      <origin 
        xyz="0 0 0"
        rpy="0 0 0" />
      <geometry>
        <mesh filename="package://biped_s40_hand/meshes/r_leg_yaw.obj" />
      </geometry>
      <material 
        name="">
        <color 
          rgba="0.650980392156863 0.619607843137255 0.588235294117647 1" />
      </material>
    </visual>
  </link>
  <joint 
    name="leg_r2_joint"
    type="revolute">
    <origin 
      xyz="0.1365 0.0010866 -0.033901"
      rpy="0 0 0" />
    <parent 
      link="leg_r1_link" />
    <child 
      link="leg_r2_link" />
    <axis 
      xyz="0 0 1" />
    <limit
      lower="-1.04"
      upper="0.52"
      effort="60"
      velocity="14" />
  </joint>

  <link name="leg_r3_link">
    <inertial>
      <origin 
        xyz="-0.00644903 0.09813560 -0.05357606"
        rpy="0 0 0" />
      <mass 
        value="2.46657141"/>
      <inertia 
        ixx="0.02254838"
        ixy="0.00023457"
        ixz="0.00013808"
        iyy="0.02319666"
        iyz="0.00259984"
        izz="0.00432904" />
    </inertial>
    <visual>
      <origin 
        xyz="0 0 0"
        rpy="0 0 0" />
      <geometry>
        <mesh filename="package://biped_s40_hand/meshes/r_leg_pitch.obj" />
      </geometry>
      <material 
        name="">
        <color 
          rgba="0.529411764705882 0.549019607843137 0.549019607843137 1" />
      </material>
    </visual>
  </link>
  <joint name="leg_r3_joint"
    type="revolute">
    <origin 
      xyz="0 -0.094 -0.09"
      rpy="0 0 0" />
    <parent 
      link="leg_r2_link" />
    <child 
      link="leg_r3_link" />
    <axis xyz="0 1 0" />
    <limit
      lower="-1.83"
      upper="1.04"
      effort="85"
      velocity="14" />
  </joint>

  <link name="leg_r4_link">
    <inertial>
      <origin 
        xyz="0.00080045 0.00004225 -0.12049699"
        rpy="0 0 0" />
      <mass 
        value="1.62911540" />
      <inertia 
        ixx="0.01343597"
        ixy="0.00000234"
        ixz="0.00020391"
        iyy="0.01359234"
        iyz="-0.00018311"
        izz="0.00092149" />
    </inertial>
    <visual>
      <origin 
        xyz="0 0 0"
        rpy="0 0 0" />
      <geometry>
        <mesh 
          filename="package://biped_s40_hand/meshes/r_knee.obj" />
      </geometry>
      <material 
        name="">
        <color 
          rgba="0.686274509803922 0.658823529411765 0.63921568627451 1" />
      </material>
    </visual>
  </link>
  <joint 
    name="leg_r4_joint"
    type="revolute">
    <origin 
      xyz="0.004136 0.06635 -0.24997"
      rpy="0 0 0" />
    <parent 
      link="leg_r3_link" />
    <child 
      link="leg_r4_link" />
    <axis 
      xyz="0 1 0" />
    <limit
      lower="-0.0"
      upper="2.18"
      effort="85"
      velocity="14" />
  </joint>

  <link name="leg_r5_link">
    <inertial>
      <origin 
        xyz="0 0.02100018 0"
        rpy="0 0 0" />
      <mass 
        value="0.05444454"/>
      <inertia 
        ixx="0.00000411"
        ixy="0"
        ixz="0"
        iyy="0.00000411"
        iyz="0"
        izz="0.00000728"/>
    </inertial>
    <visual>
      <origin 
        xyz="0 0 0"
        rpy="0 0 0" />
      <geometry>
        <mesh 
          filename="package://biped_s40_hand/meshes/r_foot_pitch.obj" />
      </geometry>
      <material 
        name="">
        <color rgba="0.690196078431373 0.658823529411765 0.63921568627451 1" />
      </material>
    </visual>
  </link>
  <joint name="leg_r5_joint"
    type="revolute">
    <origin 
      xyz="0 0.0022 -0.346"
      rpy="0 0 0" />
    <parent 
      link="leg_r4_link" />
    <child 
      link="leg_r5_link" />
    <axis 
      xyz="0 1 0" />
    <limit
      lower="-0.61"
      upper="0.52"
      effort="36"
      velocity="14" />
  </joint>

  <link name="leg_r6_link">
    <inertial>
      <origin 
        xyz="-0.03594837 -0.00000972 -0.02713025"
        rpy="0 0 0" />
      <mass 
        value="0.46707428" />
      <inertia 
        ixx="0.00040710"
        ixy="-0.00000016"
        ixz="-0.00023147"
        iyy="0.00127525"
        iyz="0.00000006"
        izz="0.00135359" />
    </inertial>
    <visual>
      <origin 
        xyz="0 0 0"
        rpy="0 0 0" />
      <geometry>
        <mesh 
          filename="package://biped_s40_hand/meshes/r_foot_roll.obj" />
      </geometry>
      <material 
        name="">
        <color 
          rgba="0.690196078431373 0.658823529411765 0.63921568627451 1" />
      </material>
    </visual>
    <visual>
      <origin rpy="0 0 0" xyz="-0.09 0.05 -0.0465" />
      <geometry>
        <sphere radius="0.005" />
      </geometry>
    </visual>
    <collision>
      <origin rpy="0 0 0" xyz="-0.09 0.05 -0.0465" />
      <geometry>
        <sphere radius="0.005" />
      </geometry>
    </collision>
    <visual>
      <origin rpy="0 0 0" xyz="-0.09 -0.05 -0.0465" />
      <geometry>
        <sphere radius="0.005" />
      </geometry>
    </visual>
    <collision>
      <origin rpy="0 0 0" xyz="-0.09 -0.05 -0.0465" />
      <geometry>
        <sphere radius="0.005" />
      </geometry>
    </collision>

    <visual>
      <origin rpy="0 0 0" xyz="0.15 0.05 -0.0465" />
      <geometry>
        <sphere radius="0.005" />
      </geometry>
    </visual>
    <collision>
      <origin rpy="0 0 0" xyz="0.15 0.05 -0.0465" />
      <geometry>
        <sphere radius="0.005" />
      </geometry>
    </collision>
    <visual>
      <origin rpy="0 0 0" xyz="0.15 -0.05 -0.0465" />
      <geometry>
        <sphere radius="0.005" />
      </geometry>
    </visual>
    <collision>
      <origin rpy="0 0 0" xyz="0.15 -0.05 -0.0465" />
      <geometry>
        <sphere radius="0.005" />
      </geometry>
    </collision>
  </link>
  <joint 
    name="leg_r6_joint"
    type="revolute">
    <origin 
      xyz="0 0 0"
      rpy="0 0 0" />
    <parent 
      link="leg_r5_link" />
    <child 
      link="leg_r6_link" />
    <axis 
      xyz="1 0 0" />
    <limit
      lower="-0.52"
      upper="0.61"
      effort="36"
      velocity="14" />
  </joint>

  <link name="rl_foot_toe">
    <collision>
      <origin 
        rpy="0 0 0"
        xyz="0 0 0"/>
      <geometry>
        <sphere radius="0.005"/>
      </geometry>
    </collision>
  </link>
  <joint 
    name="rl_foot_toe_joint"
    type="fixed">
    <origin 
      xyz="0.15 0.05 -0.0465"
      rpy="0 0 0" />
    <parent 
      link="leg_r6_link" />
    <child 
      link="rl_foot_toe" />
  </joint>
  <link 
    name="rl_foot_heel">
    <collision>
      <origin 
        rpy="0 0 0"
        xyz="0 0 0"/>
      <geometry>
        <sphere radius="0.005"/>
      </geometry>
    </collision>
  </link>
  <joint 
    name="rl_foot_heel_joint"
    type="fixed">
    <origin 
      xyz="-0.09 0.05 -0.0465"
      rpy="0 0 0" />
    <parent 
      link="leg_r6_link" />
    <child 
      link="rl_foot_heel" />
  </joint>

  <link 
    name="rr_foot_toe">
    <collision>
      <origin 
        rpy="0 0 0"
        xyz="0 0 0"/>
      <geometry>
        <sphere radius="0.005"/>
      </geometry>
    </collision>
  </link>
  <joint 
    name="rr_foot_toe_joint"
    type="fixed">
    <origin 
      xyz="0.15 -0.05 -0.0465"
      rpy="0 0 0" />
    <parent 
      link="leg_r6_link" />
    <child 
      link="rr_foot_toe" />
  </joint>
  <link 
    name="rr_foot_heel">
    <collision>
      <origin 
        rpy="0 0 0"
        xyz="0 0 0"/>
      <geometry>
        <sphere radius="0.005"/>
      </geometry>
    </collision>
  </link>
  <joint 
    name="rr_foot_heel_joint"
    type="fixed">
    <origin 
      xyz="-0.09 -0.05 -0.0465"
      rpy="0 0 0" />
    <parent 
      link="leg_r6_link" />
    <child 
      link="rr_foot_heel" />
  </joint>
  <link 
    name="r_foot_toe">
    <collision>
      <origin 
        rpy="0 0 0"
        xyz="0 0 0"/>
      <geometry>
        <sphere radius="0.005"/>
      </geometry>
    </collision>
  </link>
  <joint 
    name="r_foot_toe_joint"
    type="fixed">
    <origin 
      xyz="0.15 -0.0 -0.0465"
      rpy="0 0 0" />
    <parent 
      link="leg_r6_link" />
    <child 
      link="r_foot_toe" />
  </joint>
  <link 
    name="r_foot_heel">
    <collision>
      <origin 
        rpy="0 0 0"
        xyz="0 0 0"/>
      <geometry>
        <sphere radius="0.005"/>
      </geometry>
    </collision>
  </link>
  <joint 
    name="r_foot_heel_joint"
    type="fixed">
    <origin 
      xyz="-0.09 -0.0 -0.0465"
      rpy="0 0 0" />
    <parent 
      link="leg_r6_link" />
    <child 
      link="r_foot_heel" />
  </joint>

  <!-- ************************************************************ -->
  <!-- ********************** Left arm* *************************** -->
  <!-- ************************************************************ -->
  <link
    name="zarm_l1_link">
    <inertial>
      <origin
        xyz="0.0146835191418715 -0.0166604103758634 -6.82857133371129E-05"
        rpy="0 0 0" />
      <mass
        value="0.794" />
      <inertia
        ixx="0.0002674432873971"
        ixy="-2.5654089149164E-05"
        ixz="-1.72966133127553E-07"
        iyy="0.000125796784291983"
        iyz="-1.66717296343013E-06"
        izz="0.000196186976742156" />
    </inertial>
    <visual>
      <origin
        xyz="0 0 0"
        rpy="0 0 0" />
      <geometry>
        <mesh
          filename="package://biped_s40_hand/meshes/l_arm_pitch.obj" />
      </geometry>
      <material
        name="">
        <color
          rgba="1 1 1 1" />
      </material>
    </visual>    
  </link>
  <joint
    name="zarm_l1_joint"
    type="revolute">
    <origin
      xyz="-0.0175475823124921 0.254700000000031 0.324500000000024"
      rpy="0 0 0" />
    <parent
      link="base_link" />
    <child
      link="zarm_l1_link" />
    <axis
      xyz="0 1 0" />
    <limit 
      lower="-2.0933" 
      upper="0.5233" 
      effort="60" 
      velocity="14" />
    <dynamic
      damping="0.2" />
  </joint>

  <link
    name="zarm_l2_link">
    <inertial>
      <origin
        xyz="0.0222872651779299 0.0156945544195473 -0.0202262244341484"
        rpy="0 0 0" />
      <mass
        value="0.20735" />
      <inertia
        ixx="0.000160370067223081"
        ixy="6.30811840859269E-06"
        ixz="-1.13259246453495E-05"
        iyy="0.000262365778589962"
        iyz="3.14941259087024E-05"
        izz="0.00023601403628197" />
    </inertial>
    <visual>
      <origin
        xyz="0 0 0"
        rpy="0 0 0" />
      <geometry>
        <mesh
          filename="package://biped_s40_hand/meshes/l_arm_roll.obj" />
      </geometry>
      <material
        name="">
        <color
          rgba="1 1 1 1" />
      </material>
    </visual>   
  </link>
  <joint
    name="zarm_l2_joint"
    type="revolute">
    <origin
      xyz="0 0 0"
      rpy="0 0 0" />
    <parent
      link="zarm_l1_link" />
    <child
      link="zarm_l2_link" />
    <axis
      xyz="1 0 0" />
    <limit 
      lower="-0.3489" 
      upper="2.0933" 
      effort="82.8" 
      velocity="14" />
    <dynamic
      damping="0.2" />
  </joint>

  <link
    name="zarm_l3_link">
    <inertial>
      <origin
        xyz="6.16940440451783E-05 0.00525815062784063 -0.128821944854616"
        rpy="0 0 0" />
      <mass
        value="1.120632" />
      <inertia
        ixx="7.00575957554699E-05"
        ixy="-6.81658291272877E-10"
        ixz="2.69427050743199E-10"
        iyy="8.53612265336777E-05"
        iyz="6.95899873075699E-06"
        izz="8.82223899453285E-05" />
    </inertial>
    <visual>
      <origin
        xyz="0 0 0"
        rpy="0 0 0" />
      <geometry>
        <mesh
          filename="package://biped_s40_hand/meshes/l_arm_yaw.obj" />
      </geometry>
      <material
        name="">
        <color
          rgba="1 1 1 1" />
      </material>
    </visual>    
  </link>
  <joint
    name="zarm_l3_joint"
    type="revolute">
    <origin
      xyz="0 0 0"
      rpy="0 0 0" />
    <parent
      link="zarm_l2_link" />
    <child
      link="zarm_l3_link" />
    <axis
      xyz="0 0 1" />
    <limit 
      lower="-1.57" 
      upper="1.57" 
      effort="60" 
      velocity="14" />
    <dynamic
      damping="0.2" />
  </joint>
  
  <link
    name="zarm_l4_link">
    <inertial>
      <origin
        xyz="-1.4281929799409E-05 0.00938313949959718 -0.0522687552263489"
        rpy="0 0 0" />
      <mass
        value="0.395825" />
      <inertia
        ixx="9.558084476069E-05"
        ixy="-4.53863490387433E-08"
        ixz="5.39342118513253E-08"
        iyy="0.000126326373178391"
        iyz="-9.58160032696958E-06"
        izz="0.000121032474884238" />
    </inertial>
    <visual>
      <origin
        xyz="0 0 0"
        rpy="0 0 0" />
      <geometry>
        <mesh
          filename="package://biped_s40_hand/meshes/l_forearm_pitch.obj" />
      </geometry>
      <material
        name="">
        <color
          rgba="1 1 1 1" />
      </material>
    </visual>    
  </link>
  <joint
    name="zarm_l4_joint"
    type="revolute">
    <origin
      xyz="0 0 -0.163599999999998"
      rpy="0 0 0" />
    <parent
      link="zarm_l3_link" />
    <child
      link="zarm_l4_link" />
    <axis
      xyz="0 1 0" />
    <limit lower="-2.0933" upper="0" effort="60" velocity="14" />
    <dynamic
      damping="0.2" />
  </joint>
  
  <link
    name="zarm_l5_link">
    <inertial>
      <origin
        xyz="0.000113133463122583 0.00969227839919062 0.0817960696431681"
        rpy="0 0 0" />
      <mass
        value="0.380792" />
      <inertia
        ixx="7.64923984145487E-05"
        ixy="8.51098127601464E-09"
        ixz="-1.4070355859132E-08"
        iyy="0.000122231132554914"
        iyz="1.11226968994633E-06"
        izz="8.44935061342021E-05" />
    </inertial>
    <visual>
      <origin
        xyz="0 0 0"
        rpy="0 0 0" />
      <geometry>
        <mesh
          filename="package://biped_s40_hand/meshes/l_hand_yaw.obj" />
      </geometry>
      <material
        name="">
        <color
          rgba="1 1 1 1" />
      </material>
    </visual>   
  </link>
  <joint
    name="zarm_l5_joint"
    type="revolute">
    <origin
      xyz="0 0 -0.191049997298861"
      rpy="0 0 0" />
    <parent
      link="zarm_l4_link" />
    <child
      link="zarm_l5_link" />
    <axis
      xyz="0 0 1" />
    <limit 
      lower="-1.657" 
      upper="1.657" 
      effort="6" 
      velocity="14" />
    <dynamic
      damping="0.2" />
  </joint>
  
  <link
    name="zarm_l6_link">
    <inertial>
      <origin
        xyz="0.00810609786663821 0.00489663150092601 0.00622488608908427"
        rpy="0 0 0" />
      <mass
        value="0.376651" />
      <inertia
        ixx="4.77321490368476E-05"
        ixy="3.05261917457107E-06"
        ixz="4.77827164947654E-06"
        iyy="3.43814769749139E-05"
        iyz="-4.59311499587155E-06"
        izz="2.49955336560135E-05" />
    </inertial>
    <visual>
      <origin
        xyz="0 0 0"
        rpy="0 0 0" />
      <geometry>
        <mesh
          filename="package://biped_s40_hand/meshes/l_hand_pitch.obj" />
      </geometry>
      <material
        name="">
        <color
          rgba="1 1 1 1" />
      </material>
    </visual>    
  </link>
  <joint
    name="zarm_l6_joint"
    type="revolute">
    <origin
      xyz="0 0 0"
      rpy="0 0 0" />
    <parent
      link="zarm_l5_link" />
    <child
      link="zarm_l6_link" />
    <axis
      xyz="0 1 0" />
    <limit 
      lower="-1.657" 
      upper="1.657" 
      effort="6" 
      velocity="14" />
    <dynamic
      damping="0.2" />
  </joint>
  
  <link
    name="zarm_l7_link">
    <inertial>
      <origin
        xyz="0.0055750097939089 0.00647363667890594 -0.0826245715087526"
        rpy="0 0 0" />
      <mass
        value="0.704669" />
      <inertia
        ixx="8.04371746531483E-05"
        ixy="2.770174858381E-07"
        ixz="-4.63354764745673E-06"
        iyy="0.000116536814280971"
        iyz="1.04534418501281E-05"
        izz="0.000111690600253046" />
    </inertial>
    <visual>
      <origin
        xyz="0 0 0"
        rpy="0 0 0" />
      <geometry>
        <mesh
          filename="package://biped_s40_hand/meshes/l_hand_roll.STL" />
      </geometry>
      <material
        name="">
        <color
          rgba="1 1 1 1" />
      </material>
    </visual>   
  </link>
  <joint
    name="zarm_l7_joint"
    type="revolute">
    <origin
      xyz="0 0 0"
      rpy="0 0 0" />
    <parent
      link="zarm_l6_link" />
    <child
      link="zarm_l7_link" />
    <axis
      xyz="1 0 0" />
    <limit 
      lower="-1.57" 
      upper="1.57" 
      effort="6" 
      velocity="14" />
    <dynamic
      damping="0.2" />
  </joint>

  <link
    name="zarm_l7_end_effector">
    <collision>
        <origin rpy="0 0 0" xyz="0 0 0"/>
        <geometry>
            <sphere radius="0.005"/>
        </geometry>
    </collision>
  </link>
  <joint
    name="zarm_l7_joint_end_effector"
    type="fixed">
    <origin
      xyz="0.00 -0.03 -0.17"
      rpy="0 0 0" />
    <parent
      link="zarm_l7_link" />
    <child
      link="zarm_l7_end_effector" />
  </joint>

  <!-- ************************************************************ -->
  <!-- ********************** Right arm *************************** -->
  <!-- ************************************************************ -->
  <link
    name="zarm_r1_link">
    <inertial>
      <origin
        xyz="0.0146743511434554 0.0168298008224051 -8.16711977456031E-05"
        rpy="0 0 0" />
      <mass
        value="0.794" />
      <inertia
        ixx="0.000267364314112701"
        ixy="2.58822573731612E-05"
        ixz="-1.74450019197634E-07"
        iyy="0.000125724274127356"
        iyz="1.71810516637517E-06"
        izz="0.000196179895851995" />
    </inertial>
    <visual>
      <origin
        xyz="0 0 0"
        rpy="0 0 0" />
      <geometry>
        <mesh
          filename="package://biped_s40_hand/meshes/r_arm_pitch.obj" />
      </geometry>
      <material
        name="">
        <color
          rgba="1 1 1 1" />
      </material>
    </visual>   
  </link>
  <joint
    name="zarm_r1_joint"
    type="revolute">
    <origin
      xyz="-0.0175475823119764 -0.254700000000003 0.324500000000024"
      rpy="0 0 0" />
    <parent
      link="base_link" />
    <child
      link="zarm_r1_link" />
    <axis
      xyz="0 1 0" />
    <limit 
      lower="-2.0933" 
      upper="0.5233" 
      effort="60" 
      velocity="14" />
    <dynamic
      damping="0.2" />
  </joint>
  
  <link
    name="zarm_r2_link">
    <inertial>
      <origin
        xyz="0.0223009070030529 -0.0156950170482436 -0.0202307747650334"
        rpy="0 0 0" />
      <mass
        value="0.20735" />
      <inertia
        ixx="0.00016058853411588"
        ixy="-6.25733649402466E-06"
        ixz="-1.13236198708706E-05"
        iyy="0.000262566981542989"
        iyz="-3.14930415013909E-05"
        izz="0.000236151535262186" />
    </inertial>
    <visual>
      <origin
        xyz="0 0 0"
        rpy="0 0 0" />
      <geometry>
        <mesh
          filename="package://biped_s40_hand/meshes/r_arm_roll.obj" />
      </geometry>
      <material
        name="">
        <color
          rgba="1 1 1 1" />
      </material>
    </visual>   
  </link>
  <joint
    name="zarm_r2_joint"
    type="revolute">
    <origin
      xyz="0 0 0"
      rpy="0 0 0" />
    <parent
      link="zarm_r1_link" />
    <child
      link="zarm_r2_link" />
    <axis
      xyz="1 0 0" />
    <limit 
      lower="-2.0933" 
      upper="0.3489" 
      effort="82.8" 
      velocity="14" />
    <dynamic
      damping="0.2" />
  </joint>
  
  <link
    name="zarm_r3_link">
    <inertial>
      <origin
        xyz="-4.82749435400213E-05 -0.0052581506278393 -0.128821944854617"
        rpy="0 0 0" />
      <mass
        value="1.120632" />
      <inertia
        ixx="7.00575957554697E-05"
        ixy="-6.81658260938682E-10"
        ixz="-2.69427064597612E-10"
        iyy="8.53612265336775E-05"
        iyz="-6.95899873075696E-06"
        izz="8.82223899453284E-05" />
    </inertial>
    <visual>
      <origin
        xyz="0 0 0"
        rpy="0 0 0" />
      <geometry>
        <mesh
          filename="package://biped_s40_hand/meshes/r_arm_yaw.obj" />
      </geometry>
      <material
        name="">
        <color
          rgba="1 1 1 1" />
      </material>
    </visual>    
  </link>
  <joint
    name="zarm_r3_joint"
    type="revolute">
    <origin
      xyz="0 0 0"
      rpy="0 0 0" />
    <parent
      link="zarm_r2_link" />
    <child
      link="zarm_r3_link" />
    <axis
      xyz="0 0 1" />
    <limit 
      lower="-1.57" 
      upper="1.57" 
      effort="60" 
      velocity="14" />
    <dynamic
      damping="0.2" />
  </joint>
  
  <link
    name="zarm_r4_link">
    <inertial>
      <origin
        xyz="-0.000127232990745116 -0.00951602649232586 -0.0522687552263488"
        rpy="0 0 0" />
      <mass
        value="0.395825" />
      <inertia
        ixx="9.55808447606916E-05"
        ixy="-4.53863489774233E-08"
        ixz="-5.41060583443891E-08"
        iyy="0.000126326373178394"
        iyz="9.40982665987077E-06"
        izz="0.00012103247488424" />
    </inertial>
    <visual>
      <origin
        xyz="0 0 0"
        rpy="0 0 0" />
      <geometry>
        <mesh
          filename="package://biped_s40_hand/meshes/r_forearm_pitch.obj" />
      </geometry>
      <material
        name="">
        <color
          rgba="1 1 1 1" />
      </material>
    </visual>   
  </link>
  <joint
    name="zarm_r4_joint"
    type="revolute">
    <origin
      xyz="0 0 -0.1636"
      rpy="0 0 0" />
    <parent
      link="zarm_r3_link" />
    <child
      link="zarm_r4_link" />
    <axis
      xyz="0 1 0" />
    <limit 
      lower="-2.0933" 
      upper="0" 
      effort="60" 
      velocity="14" />
    <dynamic
      damping="0.2" />
  </joint>
  
  <link
    name="zarm_r5_link">
    <inertial>
      <origin
        xyz="-0.000113133331993445 -0.0097448351680483 0.0817960724173413"
        rpy="0 0 0" />
      <mass
        value="0.380792" />
      <inertia
        ixx="7.64923982725728E-05"
        ixy="8.51115986496426E-09"
        ixz="1.40703608309957E-08"
        iyy="0.000122231132626729"
        iyz="-1.11226978982942E-06"
        izz="8.44935061081861E-05" />
    </inertial>
    <visual>
      <origin
        xyz="0 0 0"
        rpy="0 0 0" />
      <geometry>
        <mesh
          filename="package://biped_s40_hand/meshes/r_hand_yaw.obj" />
      </geometry>
      <material
        name="">
        <color
          rgba="1 1 1 1" />
      </material>
    </visual>
  </link>
  <joint
    name="zarm_r5_joint"
    type="revolute">
    <origin
      xyz="0 0 -0.191050000125729"
      rpy="0 0 0" />
    <parent
      link="zarm_r4_link" />
    <child
      link="zarm_r5_link" />
    <axis
      xyz="0 0 1" />
    <limit 
      lower="-1.657" 
      upper="1.657" 
      effort="6" 
      velocity="14" />
    <dynamic
      damping="0.2" />
  </joint>
  
  <link
    name="zarm_r6_link">
    <inertial>
      <origin
        xyz="0.00735986990228184 -0.0047523802551166 0.00605888061339196"
        rpy="0 0 0" />
      <mass
        value="0.376651" />
      <inertia
        ixx="4.77321358097824E-05"
        ixy="-2.99709432812988E-06"
        ixz="4.71488437974188E-06"
        iyy="3.42470226388499E-05"
        iyz="4.61094199971347E-06"
        izz="2.51299600072388E-05" />
    </inertial>
    <visual>
      <origin
        xyz="0 0 0"
        rpy="0 0 0" />
      <geometry>
        <mesh
          filename="package://biped_s40_hand/meshes/r_hand_pitch.obj" />
      </geometry>
      <material
        name="">
        <color
          rgba="1 1 1 1" />
      </material>
    </visual>
  </link>
  <joint
    name="zarm_r6_joint"
    type="revolute">
    <origin
      xyz="0 0 0"
      rpy="0 0 0" />
    <parent
      link="zarm_r5_link" />
    <child
      link="zarm_r6_link" />
    <axis
      xyz="0 1 0" />
    <limit 
      lower="-1.657" 
      upper="1.657" 
      effort="6" 
      velocity="14" />
    <dynamic
      damping="0.2" />
  </joint>
  
  <link
    name="zarm_r7_link">
    <inertial>
      <origin
        xyz="0.0045944493552252 -0.00586927010446042 -0.0836324643988434"
        rpy="0 0 0" />
      <mass
        value="0.704669" />
      <inertia
        ixx="0.000160651543151659"
        ixy="-5.37963063503334E-07"
        ixz="-9.47669219939636E-06"
        iyy="0.000229393712149694"
        iyz="-2.08351527945055E-05"
        izz="0.000219277776699058" />
    </inertial>
    <visual>
      <origin
        xyz="0 0 0"
        rpy="0 0 0" />
      <geometry>
        <mesh
          filename="package://biped_s40_hand/meshes/r_hand_roll.STL" />
      </geometry>
      <material
        name="">
        <color
          rgba="1 1 1 1" />
      </material>
    </visual>
  </link>
  <joint
    name="zarm_r7_joint"
    type="revolute">
    <origin
      xyz="0 0 0"
      rpy="0 0 0" />
    <parent
      link="zarm_r6_link" />
    <child
      link="zarm_r7_link" />
    <axis
      xyz="1 0 0" />
    <limit 
      lower="-1.57" 
      upper="1.57" 
      effort="6" 
      velocity="14" />
    <dynamic
      damping="0.2" />
  </joint>

  <link
    name="zarm_r7_end_effector">
    <collision>
        <origin rpy="0 0 0" xyz="0 0 0"/>
        <geometry>
            <sphere radius="0.005"/>
        </geometry>
    </collision>
  </link>
  <joint
    name="zarm_r7_joint_end_effector"
    type="fixed">
    <origin
      xyz="0.00 0.03 -0.17"
      rpy="0 0 0" />
    <parent
      link="zarm_r7_link" />
    <child
      link="zarm_r7_end_effector" />
  </joint>

  <!-- ************************************************************ -->
  <!-- ********************** head joint ************************** -->
  <!-- ************************************************************ -->
  <link name="head_yaw">
        <inertial>
            <origin 
                xyz="-0.000116065796709811 0.00341283230689319 -0.00762227943283844" 
                rpy="0 0 0" />
            <mass 
                value="0.0876587232040551" />
            <inertia 
                ixx="5.29184226374934E-05" 
                ixy="-5.55749298909931E-08" 
                ixz="2.93674313773846E-07" 
                iyy="7.69981959753033E-05" 
                iyz="-9.22993448844536E-06" 
                izz="5.31017800814282E-05" />
        </inertial>
        <visual>
            <origin xyz="0 0 0" rpy="0 0 0" />
            <geometry>
                <mesh filename="package://biped_s40_hand/meshes/head_yaw.STL" />
            </geometry>
            <material name="">
                <color rgba="0.6902 0.65882 0.63922 1" />
            </material>
        </visual>
        <collision>
            <origin xyz="0 0 0" rpy="0 0 0" />
            <geometry>
                <mesh filename="package://biped_s40_hand/meshes/head_yaw.STL" />
            </geometry>
        </collision>
    </link>
    <joint 
        name="head_yaw" 
        type="fixed">
        <origin 
            xyz="-0.0175475823124929 0 0.499400000000373" rpy="0 0 0" />
        <parent 
            link="base_link" />
        <child 
            link="head_yaw" />
        <axis 
            xyz="0 0 1" />
        <limit 
            velocity="1" 
            effort="20" 
            lower="-1.5708" 
            upper="1.5708" />
    </joint>

    <link name="head_pitch">
        <inertial>
            <origin 
                xyz="0.0108076765997382 -0.00100494759438114 0.0523165975702757" 
                rpy="0 0 0" />
            <mass 
                value="0.348142076778321" />
            <inertia 
                ixx="0.000904070873567589" 
                ixy="1.57558780381555E-06" 
                ixz="0.000295083531658369" 
                iyy="0.000957585537827452" 
                iyz="-9.61289176090918E-06" 
                izz="0.00114051835139601" />
        </inertial>
        <visual>
            <origin xyz="0 0 0" rpy="0 0 0" />
            <geometry>
                <mesh filename="package://biped_s40_hand/meshes/head_pitch.STL" />
            </geometry>
            <material name="">
                <color rgba="0.6902 0.65882 0.63922 1" />
            </material>
        </visual>
        <collision>
            <origin xyz="0 0 0" rpy="0 0 0" />
            <geometry>
                <mesh filename="package://biped_s40_hand/meshes/head_pitch.STL" />
            </geometry>
        </collision>
    </link>
    <joint 
        name="head_pitch" 
        type="fixed">
        <origin 
            xyz="0 0 0" 
            rpy="0 0 0" />
        <parent 
            link="head_yaw" />
        <child 
            link="head_pitch" />
        <axis 
            xyz="0 1 0" />
        <limit 
            velocity="1" 
            effort="20" 
            lower="-0.8708" 
            upper="0.5708" />
    </joint>

    <link name="head_camera">
        <visual>
            <origin xyz="0 0 0" rpy="0 0 0" />
            <geometry>
                <sphere radius="0.001"/>
                <!-- <box size="0.1 0.051 0.051"/> -->
            </geometry>
            <material name="">
                <color rgba="0.6902 0.65882 0.63922 1" />
            </material>
        </visual>
    </link>
    <joint name="head_camera" type="fixed">
        <origin xyz="0.082 0.0175 0.05449" rpy="0 0.6105555 0" />
        <parent link="head_pitch" />
        <child link="head_camera" />
    </joint>
  
  <!-- ************************************************************ -->
  <!-- *************** Left qiangnao hand ************************* -->
  <!-- ************************************************************ -->

  <link name="l_thumb_proximal_yaw">
      <inertial>
          <origin xyz="0.00590166593878135 -0.00373751061980748 0.000119122170746666" rpy="0 0 0" />
          <mass value="0.00177457706476174" />
          <inertia ixx="5.5194777085443E-08" ixy="3.05430802968252E-08" ixz="8.99312903596649E-10" iyy="7.93062784538195E-08" iyz="-4.09905263561327E-10" izz="9.86616855273954E-08" />
      </inertial>
      <visual>
          <origin xyz="0 0 0" rpy="0 0 0" />
          <geometry>
              <mesh filename="package://biped_s40_hand/meshes/l_thumb_proximal_yaw.STL" />
          </geometry>
          <material name="">
              <color rgba="1 1 1 0.25" />
          </material>
      </visual>
      <collision>
          <origin xyz="0 0 0" rpy="0 0 0" />
          <geometry>
              <mesh filename="package://biped_s40_hand/meshes/l_thumb_proximal_yaw.STL" />
          </geometry>
      </collision>
  </link>
  <joint name="l_thumb_proximal_yaw_joint" type="continuous">
      <origin xyz="0.0250000027597683 -0.0216278329431251 -0.110700000402975" rpy="0 0 0" />
      <parent link="zarm_l7_link" />
      <child link="l_thumb_proximal_yaw" />
      <axis xyz="0 0 -1" />
  </joint>
  <link name="l_thumb_distal_pitch">
      <inertial>
          <origin xyz="0.00835400575954671 -1.54980826169715E-06 -0.0372051471727699" rpy="0 0 0" />
          <mass value="0.0143594964918226" />
          <inertia ixx="7.15388390483937E-06" ixy="-6.69701976384447E-11" ixz="-2.03395115704228E-07" iyy="6.87910901050402E-06" iyz="5.38324327216661E-12" izz="9.1475596956079E-07" />
      </inertial>
      <visual>
          <origin xyz="0 0 0" rpy="0 0 0" />
          <geometry>
              <mesh filename="package://biped_s40_hand/meshes/l_thumb_distal_pitch.STL" />
          </geometry>
          <material name="">
              <color rgba="1 1 1 1" />
          </material>
      </visual>
      <collision>
          <origin xyz="0 0 0" rpy="0 0 0" />
          <geometry>
              <mesh filename="package://biped_s40_hand/meshes/l_thumb_distal_pitch.STL" />
          </geometry>
      </collision>
  </link>
  <joint name="l_thumb_distal_pitch_joint" type="continuous">
      <origin xyz="0.0120000000000023 -0.00649999999999773 0" rpy="0 0 0" />
      <parent link="l_thumb_proximal_yaw" />
      <child link="l_thumb_distal_pitch" />
      <axis xyz="0 1 0" />
  </joint>
  <link name="l_index_proximal_finger">
      <inertial>
          <origin xyz="0.000112677527646918 0.00210468432487104 -0.0171028451759692" rpy="0 0 0" />
          <mass value="0.00213736998836043" />
          <inertia ixx="3.18607074297438E-07" ixy="1.30056260562274E-09" ixz="2.05323306383889E-09" iyy="3.41865494200988E-07" iyz="3.87251682723715E-08" izz="9.68025640372966E-08" />
      </inertial>
      <visual>
          <origin xyz="0 0 0" rpy="0 0 0" />
          <geometry>
              <mesh filename="package://biped_s40_hand/meshes/l_index_proximal_finger.STL" />
          </geometry>
          <material name="">
              <color rgba="1 1 1 1" />
          </material>
      </visual>
      <collision>
          <origin xyz="0 0 0" rpy="0 0 0" />
          <geometry>
              <mesh filename="package://biped_s40_hand/meshes/l_index_proximal_finger.STL" />
          </geometry>
      </collision>
  </link>
  <joint name="l_index_proximal_finger_joint" type="continuous">
      <origin xyz="0.0295025377507617 0.0039487923396046 -0.174730558860478" rpy="0 -0.0311675978215656 0" />
      <parent link="zarm_l7_link" />
      <child link="l_index_proximal_finger" />
      <axis xyz="-0.998506141360648 0.0546395979585239 0" />
  </joint>
  <link name="l_index_distal_finger">
      <inertial>
          <origin xyz="-8.80400428074002E-05 -0.00161951020344181 -0.0254571889170825" rpy="0 0 0" />
          <mass value="0.0050446595604151" />
          <inertia ixx="7.63510729443016E-07" ixy="9.29795250634311E-10" ixz="-1.77723934932869E-09" iyy="7.80114728886836E-07" iyz="-3.23075401001615E-08" izz="1.15370765338784E-07" />
      </inertial>
      <visual>
          <origin xyz="0 0 0" rpy="0 0 0" />
          <geometry>
              <mesh filename="package://biped_s40_hand/meshes/l_index_distal_finger.STL" />
          </geometry>
          <material name="">
              <color rgba="1 1 1 1" />
          </material>
      </visual>
      <collision>
          <origin xyz="0 0 0" rpy="0 0 0" />
          <geometry>
              <mesh filename="package://biped_s40_hand/meshes/l_index_distal_finger.STL" />
          </geometry>
      </collision>
  </link>
  <joint name="l_index_distal_finger_joint" type="continuous">
      <origin xyz="0.00013351949359549 0.00243998929947531 -0.0349145904281216" rpy="0 0 0" />
      <parent link="l_index_proximal_finger" />
      <child link="l_index_distal_finger" />
      <axis xyz="0.998506141360648 -0.0546395979585221 0" />
  </joint>
  <link name="l_middle_proximal_finger">
      <inertial>
          <origin xyz="-8.42681364791875E-08 0.00270210130078863 -0.0207829689336636" rpy="0 0 0" />
          <mass value="0.00260456391453855" />
          <inertia ixx="5.09608185934252E-07" ixy="-1.75213111801256E-12" ixz="-1.78265353217213E-12" iyy="5.36695797641851E-07" iyz="5.70433108286832E-08" izz="1.25808947550621E-07" />
      </inertial>
      <visual>
          <origin xyz="0 0 0" rpy="0 0 0" />
          <geometry>
              <mesh filename="package://biped_s40_hand/meshes/l_middle_proximal_finger.STL" />
          </geometry>
          <material name="">
              <color rgba="1 1 1 1" />
          </material>
      </visual>
      <collision>
          <origin xyz="0 0 0" rpy="0 0 0" />
          <geometry>
              <mesh filename="package://biped_s40_hand/meshes/l_middle_proximal_finger.STL" />
          </geometry>
      </collision>
  </link>
  <joint name="l_middle_proximal_finger_joint" type="continuous">
      <origin xyz="0.00850000275976636 0.00820381922686209 -0.178435376742696" rpy="0 0 0" />
      <parent link="zarm_l7_link" />
      <child link="l_middle_proximal_finger" />
      <axis xyz="-1 0 0" />
  </joint>
  <link name="l_middle_distal_finger">
      <inertial>
          <origin xyz="6.04648922300846E-07 -0.00162350982455478 -0.0254571915129888" rpy="0 0 0" />
          <mass value="0.00504466861649399" />
          <inertia ixx="7.63455312842206E-07" ixy="1.85533672652204E-11" ixz="-1.04806627113088E-11" iyy="7.80159394341909E-07" iyz="-3.23975147926483E-08" izz="1.15374581207705E-07" />
      </inertial>
      <visual>
          <origin xyz="0 0 0" rpy="0 0 0" />
          <geometry>
              <mesh filename="package://biped_s40_hand/meshes/l_middle_distal_finger.STL" />
          </geometry>
          <material name="">
              <color rgba="1 1 1 1" />
          </material>
      </visual>
      <collision>
          <origin xyz="0 0 0" rpy="0 0 0" />
          <geometry>
              <mesh filename="package://biped_s40_hand/meshes/l_middle_distal_finger.STL" />
          </geometry>
      </collision>
  </link>
  <joint name="l_middle_distal_finger_joint" type="continuous">
      <origin xyz="0 0.00292977189725752 -0.0418976901109154" rpy="0 0 0" />
      <parent link="l_middle_proximal_finger" />
      <child link="l_middle_distal_finger" />
      <axis xyz="1 0 0" />
  </joint>
  <link name="l_ring_proximal_finger">
      <inertial>
          <origin xyz="-0.000147796548979496 0.00269934539278621 -0.0207828033089016" rpy="0 0 0" />
          <mass value="0.00260456483338844" />
          <inertia ixx="5.09689336813819E-07" ixy="-1.47916431111907E-09" ixz="-3.12001764447105E-09" iyy="5.36607842012435E-07" iyz="5.69834083724575E-08" izz="1.25816049307563E-07" />
      </inertial>
      <visual>
          <origin xyz="0 0 0" rpy="0 0 0" />
          <geometry>
              <mesh filename="package://biped_s40_hand/meshes/l_ring_proximal_finger.STL" />
          </geometry>
          <material name="">
              <color rgba="1 1 1 1" />
          </material>
      </visual>
      <collision>
          <origin xyz="0 0 0" rpy="0 0 0" />
          <geometry>
              <mesh filename="package://biped_s40_hand/meshes/l_ring_proximal_finger.STL" />
          </geometry>
      </collision>
  </link>
  <joint name="l_ring_proximal_finger_joint" type="continuous">
      <origin xyz="-0.0126025322312212 0.0080785614881318 -0.176446661066021" rpy="0 0.0311675978215913 0" />
      <parent link="zarm_l7_link" />
      <child link="l_ring_proximal_finger" />
      <axis xyz="-0.998506141360648 -0.0546395979585319 0" />
  </joint>
  <link name="l_ring_distal_finger">
      <inertial>
          <origin xyz="-2.97819768621012E-05 0.000551723183689734 -0.0145820959398313" rpy="0 0 0" />
          <mass value="0.00182871318152307" />
          <inertia ixx="2.63516580484025E-07" ixy="-6.83151710625831E-10" ixz="3.36133845950725E-10" iyy="2.75945893486764E-07" iyz="-6.18248894827772E-09" izz="4.69859277660983E-08" />
      </inertial>
      <visual>
          <origin xyz="0 0 0" rpy="0 0 0" />
          <geometry>
              <mesh filename="package://biped_s40_hand/meshes/l_ring_distal_finger.STL" />
          </geometry>
          <material name="">
              <color rgba="1 1 1 1" />
          </material>
      </visual>
      <collision>
          <origin xyz="0 0 0" rpy="0 0 0" />
          <geometry>
              <mesh filename="package://biped_s40_hand/meshes/l_ring_distal_finger.STL" />
          </geometry>
      </collision>
  </link>
  <joint name="l_ring_distal_finger_joint" type="continuous">
      <origin xyz="-0.000160223392310654 0.0029279871592986 -0.0418975085137674" rpy="0 0 0" />
      <parent link="l_ring_proximal_finger" />
      <child link="l_ring_distal_finger" />
      <axis xyz="0.998506141360637 0.0546395979587272 0" />
  </joint>
  <link name="l_pinky_proximal_finger">
      <inertial>
          <origin xyz="-0.000122637015400211 0.00210212976760699 -0.0171030805340099" rpy="0 0 0" />
          <mass value="0.00213737962233864" />
          <inertia ixx="3.18608415490598E-07" ixy="-1.31059762777735E-09" ixz="-2.27735464077079E-09" iyy="3.41873917256528E-07" iyz="3.868353887277E-08" izz="9.67938996220609E-08" />
      </inertial>
      <visual>
          <origin xyz="0 0 0" rpy="0 0 0" />
          <geometry>
              <mesh filename="package://biped_s40_hand/meshes/l_pinky_proximal_finger.STL" />
          </geometry>
          <material name="">
              <color rgba="1 1 1 1" />
          </material>
      </visual>
      <collision>
          <origin xyz="0 0 0" rpy="0 0 0" />
          <geometry>
              <mesh filename="package://biped_s40_hand/meshes/l_pinky_proximal_finger.STL" />
          </geometry>
      </collision>
  </link>
  <joint name="l_pinky_proximal_finger_joint" type="continuous">
      <origin xyz="-0.0332309186593585 0.00363387338808113 -0.170227008036839" rpy="0 0.0659957839625552 0" />
      <parent link="zarm_l7_link" />
      <child link="l_pinky_proximal_finger" />
      <axis xyz="-0.998370307122329 -0.0570677654763681 0" />
  </joint>
  <link name="l_pinky_distal_finger">
      <inertial>
          <origin xyz="-2.37672426811816E-05 0.000794235285774603 -0.012715032786375" rpy="0 0 0" />
          <mass value="0.00162997770027121" />
          <inertia ixx="1.83851165948758E-07" ixy="-6.07372921831439E-10" ixz="5.80097687729223E-10" iyy="1.94700358156753E-07" iyz="-1.32219889788332E-09" izz="3.94697814103924E-08" />
      </inertial>
      <visual>
          <origin xyz="0 0 0" rpy="0 0 0" />
          <geometry>
              <mesh filename="package://biped_s40_hand/meshes/l_pinky_distal_finger.STL" />
          </geometry>
          <material name="">
              <color rgba="1 1 1 1" />
          </material>
      </visual>
      <collision>
          <origin xyz="0 0 0" rpy="0 0 0" />
          <geometry>
              <mesh filename="package://biped_s40_hand/meshes/l_pinky_distal_finger.STL" />
          </geometry>
      </collision>
  </link>
  <joint name="l_pinky_distal_finger_joint" type="continuous">
      <origin xyz="-0.000139217094110203 0.00243552926671115 -0.0349148795758059" rpy="0 0 0" />
      <parent link="l_pinky_proximal_finger" />
      <child link="l_pinky_distal_finger" />
      <axis xyz="0.998370307122341 0.0570677654761637 0" />
  </joint>

  <!-- ************************************************************ -->
  <!-- *************** Right qiangnao hand ************************ -->
  <!-- ************************************************************ -->
  <link name="r_thumb_proximal_yaw">
      <inertial>
          <origin xyz="0.0059016659387813 0.00373751061983887 0.00028087782921854" rpy="0 0 0" />
          <mass value="0.00177457706476174" />
          <inertia ixx="5.51947770854431E-08" ixy="-3.05430802968252E-08" ixz="-8.9931290359755E-10" iyy="7.93062784538199E-08" iyz="-4.09905263561892E-10" izz="9.86616855273956E-08" />
      </inertial>
      <visual>
          <origin xyz="0 0 0" rpy="0 0 0" />
          <geometry>
              <mesh filename="package://biped_s40_hand/meshes/r_thumb_proximal_yaw.STL" />
          </geometry>
          <material name="">
              <color rgba="1 1 1 0.25" />
          </material>
      </visual>
      <collision>
          <origin xyz="0 0 0" rpy="0 0 0" />
          <geometry>
              <mesh filename="package://biped_s40_hand/meshes/r_thumb_proximal_yaw.STL" />
          </geometry>
      </collision>
  </link>
  <joint name="r_thumb_proximal_yaw_joint" type="continuous">
      <origin xyz="0.0240162583145044 0.0216278329431261 -0.110700000402968" rpy="0 0 0" />
      <parent link="zarm_r7_link" />
      <child link="r_thumb_proximal_yaw" />
      <axis xyz="0 0 1" />
  </joint>
  <link name="r_thumb_distal_pitch">
      <inertial>
          <origin xyz="0.00835400525904937 -1.55022040249087E-06 -0.037205152988654" rpy="0 0 0" />
          <mass value="0.0143594976127551" />
          <inertia ixx="7.15388296788212E-06" ixy="-6.69727355587774E-11" ixz="-2.03395160081791E-07" iyy="6.87910807838939E-06" iyz="5.44431164399722E-12" izz="9.14755969331916E-07" />
      </inertial>
      <visual>
          <origin xyz="0 0 0" rpy="0 0 0" />
          <geometry>
              <mesh filename="package://biped_s40_hand/meshes/r_thumb_distal_pitch.STL" />
          </geometry>
          <material name="">
              <color rgba="1 1 1 1" />
          </material>
      </visual>
      <collision>
          <origin xyz="0 0 0" rpy="0 0 0" />
          <geometry>
              <mesh filename="package://biped_s40_hand/meshes/r_thumb_distal_pitch.STL" />
          </geometry>
      </collision>
  </link>
  <joint name="r_thumb_distal_pitch_joint" type="continuous">
      <origin xyz="0.0120000000000024 0.00650000000000001 0.00039999999999929" rpy="0 0 0" />
      <parent link="r_thumb_proximal_yaw" />
      <child link="r_thumb_distal_pitch" />
      <axis xyz="0 -1 0" />
  </joint>
  <link name="r_index_proximal_finger">
      <inertial>
          <origin xyz="0.000117630091740083 -0.00210444255674574 -0.0171028308310166" rpy="0 0 0" />
          <mass value="0.00213737899371432" />
          <inertia ixx="3.18602101869156E-07" ixy="-1.25362698289955E-09" ixz="2.18478331808027E-09" iyy="3.41870944894183E-07" iyz="-3.87179337852981E-08" izz="9.68030538354866E-08" />
      </inertial>
      <visual>
          <origin xyz="0 0 0" rpy="0 0 0" />
          <geometry>
              <mesh filename="package://biped_s40_hand/meshes/r_index_proximal_finger.STL" />
          </geometry>
          <material name="">
              <color rgba="1 1 1 1" />
          </material>
      </visual>
      <collision>
          <origin xyz="0 0 0" rpy="0 0 0" />
          <geometry>
              <mesh filename="package://biped_s40_hand/meshes/r_index_proximal_finger.STL" />
          </geometry>
      </collision>
  </link>
  <joint name="r_index_proximal_finger_joint" type="continuous">
      <origin xyz="0.0285187933054979 -0.0039487923396026 -0.174730558860479" rpy="0 -0.0311675978215671 0" />
      <parent link="zarm_r7_link" />
      <child link="r_index_proximal_finger" />
      <axis xyz="0.998506141360647 0.0546395979585406 0" />
  </joint>
  <link name="r_index_distal_finger">
      <inertial>
          <origin xyz="-8.9232232394443E-05 0.00161946515080247 -0.0254573000709627" rpy="0 0 0" />
          <mass value="0.00504466012184763" />
          <inertia ixx="7.63500198005666E-07" ixy="-8.93025400014092E-10" ixz="-1.75721366263703E-09" iyy="7.80112979178675E-07" iyz="3.23088054385963E-08" izz="1.15370268537332E-07" />
      </inertial>
      <visual>
          <origin xyz="0 0 0" rpy="0 0 0" />
          <geometry>
              <mesh filename="package://biped_s40_hand/meshes/r_index_distal_finger.STL" />
          </geometry>
          <material name="">
              <color rgba="1 1 1 1" />
          </material>
      </visual>
      <collision>
          <origin xyz="0 0 0" rpy="0 0 0" />
          <geometry>
              <mesh filename="package://biped_s40_hand/meshes/r_index_distal_finger.STL" />
          </geometry>
      </collision>
  </link>
  <joint name="r_index_distal_finger_joint" type="continuous">
      <origin xyz="0.000133519493595612 -0.00243998929947775 -0.0349145904281185" rpy="0 0 0" />
      <parent link="r_index_proximal_finger" />
      <child link="r_index_distal_finger" />
      <axis xyz="-0.998506141360649 -0.0546395979585212 0" />
  </joint>
  <link name="r_middle_proximal_finger">
      <inertial>
          <origin xyz="8.44813785091242E-08 -0.00270210141804927 -0.0207829698234612" rpy="0 0 0" />
          <mass value="0.00260456401479316" />
          <inertia ixx="5.09608239447983E-07" ixy="-1.75029152849441E-12" ixz="1.79637389141395E-12" iyy="5.36695856290199E-07" iyz="-5.70433154945367E-08" izz="1.25808948975584E-07" />
      </inertial>
      <visual>
          <origin xyz="0 0 0" rpy="0 0 0" />
          <geometry>
              <mesh filename="package://biped_s40_hand/meshes/r_middle_proximal_finger.STL" />
          </geometry>
          <material name="">
              <color rgba="1 1 1 1" />
          </material>
      </visual>
      <collision>
          <origin xyz="0 0 0" rpy="0 0 0" />
          <geometry>
              <mesh filename="package://biped_s40_hand/meshes/r_middle_proximal_finger.STL" />
          </geometry>
      </collision>
  </link>
  <joint name="r_middle_proximal_finger_joint" type="continuous">
      <origin xyz="0.00751625831450465 -0.00820381922686125 -0.178435376742697" rpy="0 0 0" />
      <parent link="zarm_r7_link" />
      <child link="r_middle_proximal_finger" />
      <axis xyz="1 0 0" />
  </joint>
  <link name="r_middle_distal_finger">
      <inertial>
          <origin xyz="-6.04521225378366E-07 0.00162350982710252 -0.025457191512641" rpy="0 0 0" />
          <mass value="0.00504466863846282" />
          <inertia ixx="7.6345530976374E-07" ixy="1.85475490772791E-11" ixz="1.04892536633895E-11" iyy="7.80159403477418E-07" iyz="3.23975164550656E-08" izz="1.15374581204344E-07" />
      </inertial>
      <visual>
          <origin xyz="0 0 0" rpy="0 0 0" />
          <geometry>
              <mesh filename="package://biped_s40_hand/meshes/r_middle_distal_finger.STL" />
          </geometry>
          <material name="">
              <color rgba="1 1 1 1" />
          </material>
      </visual>
      <collision>
          <origin xyz="0 0 0" rpy="0 0 0" />
          <geometry>
              <mesh filename="package://biped_s40_hand/meshes/r_middle_distal_finger.STL" />
          </geometry>
      </collision>
  </link>
  <joint name="r_middle_distal_finger_joint" type="continuous">
      <origin xyz="0 -0.00292977189725413 -0.0418976901109125" rpy="0 0 0" />
      <parent link="r_middle_proximal_finger" />
      <child link="r_middle_distal_finger" />
      <axis xyz="-1 0 0" />
  </joint>
  <link name="r_ring_proximal_finger">
      <inertial>
          <origin xyz="-0.000147627677307374 -0.00269935568307084 -0.0207828027334272" rpy="0 0 0" />
          <mass value="0.00260456442916689" />
          <inertia ixx="5.09688869653555E-07" ixy="1.47567826577373E-09" ixz="-3.11642075126123E-09" iyy="5.36608130664138E-07" iyz="-5.69836124932145E-08" izz="1.25816010690367E-07" />
      </inertial>
      <visual>
          <origin xyz="0 0 0" rpy="0 0 0" />
          <geometry>
              <mesh filename="package://biped_s40_hand/meshes/r_ring_proximal_finger.STL" />
          </geometry>
          <material name="">
              <color rgba="1 1 1 1" />
          </material>
      </visual>
      <collision>
          <origin xyz="0 0 0" rpy="0 0 0" />
          <geometry>
              <mesh filename="package://biped_s40_hand/meshes/r_ring_proximal_finger.STL" />
          </geometry>
      </collision>
  </link>
  <joint name="r_ring_proximal_finger_joint" type="continuous">
      <origin xyz="-0.0135862766764854 -0.00807856148813096 -0.176446661066022" rpy="0 0.0311675978215922 0" />
      <parent link="zarm_r7_link" />
      <child link="r_ring_proximal_finger" />
      <axis xyz="0.998506141360648 -0.0546395979585354 0" />
  </joint>
  <link name="r_ring_distal_finger">
      <inertial>
          <origin xyz="-3.05447320099322E-05 -0.00055182982921842 -0.014581933967133" rpy="0 0 0" />
          <mass value="0.00182869050551967" />
          <inertia ixx="2.6351019026747E-07" ixy="6.80589443443767E-10" ixz="3.40598850881854E-10" iyy="2.75942607379873E-07" iyz="6.18066814960194E-09" izz="4.69846444924734E-08" />
      </inertial>
      <visual>
          <origin xyz="0 0 0" rpy="0 0 0" />
          <geometry>
              <mesh filename="package://biped_s40_hand/meshes/r_ring_distal_finger.STL" />
          </geometry>
          <material name="">
              <color rgba="1 1 1 1" />
          </material>
      </visual>
      <collision>
          <origin xyz="0 0 0" rpy="0 0 0" />
          <geometry>
              <mesh filename="package://biped_s40_hand/meshes/r_ring_distal_finger.STL" />
          </geometry>
      </collision>
  </link>
  <joint name="r_ring_distal_finger_joint" type="continuous">
      <origin xyz="-0.000160223392313565 -0.00292798715935183 -0.0418975085136676" rpy="0 0 0" />
      <parent link="r_ring_proximal_finger" />
      <child link="r_ring_distal_finger" />
      <axis xyz="-0.996566833460806 -0.0546395979585212 -0.0622017747402293" />
  </joint>
  <link name="r_pinky_proximal_finger">
      <inertial>
          <origin xyz="-0.000117692942698921 -0.00210238254136691 -0.0171031038120715" rpy="0 0 0" />
          <mass value="0.00213737106866596" />
          <inertia ixx="3.18613658418781E-07" ixy="1.35743663351377E-09" ixz="-2.14595314636863E-09" iyy="3.4186844347216E-07" iyz="-3.86910999425676E-08" izz="9.67934520226222E-08" />
      </inertial>
      <visual>
          <origin xyz="0 0 0" rpy="0 0 0" />
          <geometry>
              <mesh filename="package://biped_s40_hand/meshes/r_pinky_proximal_finger.STL" />
          </geometry>
          <material name="">
              <color rgba="1 1 1 1" />
          </material>
      </visual>
      <collision>
          <origin xyz="0 0 0" rpy="0 0 0" />
          <geometry>
              <mesh filename="package://biped_s40_hand/meshes/r_pinky_proximal_finger.STL" />
          </geometry>
      </collision>
  </link>
  <joint name="r_pinky_proximal_finger_joint" type="continuous">
      <origin xyz="-0.0342146631046227 -0.0036338733880803 -0.17022700803684" rpy="0 0.0659957839625563 0" />
      <parent link="zarm_r7_link" />
      <child link="r_pinky_proximal_finger" />
      <axis xyz="0.998370307122331 -0.0570677654763477 0" />
  </joint>
  <link name="r_pinky_distal_finger">
      <inertial>
          <origin xyz="-6.68864174628164E-05 -0.00079192546781276 -0.0127151268014948" rpy="0 0 0" />
          <mass value="0.00162993727561191" />
          <inertia ixx="1.83853268460625E-07" ixy="6.36687597538947E-10" ixz="-4.24280859276174E-10" iyy="1.94697260253276E-07" iyz="1.38051635062388E-09" izz="3.94676279750627E-08" />
      </inertial>
      <visual>
          <origin xyz="0 0 0" rpy="0 0 0" />
          <geometry>
              <mesh filename="package://biped_s40_hand/meshes/r_pinky_distal_finger.STL" />
          </geometry>
          <material name="">
              <color rgba="1 1 1 1" />
          </material>
      </visual>
      <collision>
          <origin xyz="0 0 0" rpy="0 0 0" />
          <geometry>
              <mesh filename="package://biped_s40_hand/meshes/r_pinky_distal_finger.STL" />
          </geometry>
      </collision>
  </link>
  <joint name="r_pinky_distal_finger_joint" type="continuous">
      <origin xyz="-0.00013921709411558 -0.0024355292668054 -0.0349148795757724" rpy="0 0 0" />
      <parent link="r_pinky_proximal_finger" />
      <child link="r_pinky_distal_finger" />
      <axis xyz="-0.99837030712233 0.0570677654763578 0" />
  </joint>
</robot>
