<?xml version="1.0"?>
<robot
  name="brainco_hand">
  <link
    name="base_link">
    <inertial>
      <origin
        xyz="0.00396050555698803 0.00946265387749012 -0.066602176591173"
        rpy="0 0 0" />
      <mass
        value="0.151352919071109" />
      <inertia
        ixx="9.13246737942629E-05"
        ixy="3.25649345932988E-07"
        ixz="-4.78728976781085E-06"
        iyy="0.000139866613946359"
        iyz="1.1925397914412E-05"
        izz="0.000125082116428502" />
    </inertial>
    <visual>
      <origin
        xyz="0 0 0"
        rpy="0 0 0" />
      <geometry>
        <mesh
          filename="package://biped_s4/meshes/l_hand_roll.STL" />
      </geometry>
      <material
        name="">
        <color
          rgba="1 1 1 1" />
      </material>
    </visual>
    <collision>
      <origin
        xyz="0 0 0"
        rpy="0 0 0" />
      <geometry>
        <mesh
          filename="package://biped_s4/meshes/l_hand_roll.STL" />
      </geometry>
    </collision>
  </link>
  <link
    name="thumb1">
    <inertial>
      <origin
        xyz="0.00590166593878135 -0.00373751061980748 0.000119122170746666"
        rpy="0 0 0" />
      <mass
        value="0.00177457706476174" />
      <inertia
        ixx="5.5194777085443E-08"
        ixy="3.05430802968252E-08"
        ixz="8.99312903596649E-10"
        iyy="7.93062784538195E-08"
        iyz="-4.09905263561327E-10"
        izz="9.86616855273954E-08" />
    </inertial>
    <visual>
      <origin
        xyz="0 0 0"
        rpy="0 0 0" />
      <geometry>
        <mesh
          filename="package://biped_s4/meshes/l_thumb_proximal_yaw.STL" />
      </geometry>
      <material
        name="">
        <color
          rgba="1 1 1 0.25" />
      </material>
    </visual>
    <collision>
      <origin
        xyz="0 0 0"
        rpy="0 0 0" />
      <geometry>
        <mesh
          filename="package://biped_s4/meshes/l_thumb_proximal_yaw.STL" />
      </geometry>
    </collision>
  </link>
  <joint
    name="thumb1"
    type="revolute">
    <origin
      xyz="0.0250000027597683 -0.0216278329431251 -0.110700000402975"
      rpy="0 0 0" />
    <parent
      link="base_link" />
    <child
      link="thumb1" />
    <axis
      xyz="0 0 -1" />
    <limit
      lower="0"
      upper="1.5708"
      effort="0"
      velocity="0" />
  </joint>
  <link
    name="thumb2">
    <inertial>
      <origin
        xyz="0.00835400575954671 -1.54980826169715E-06 -0.0372051471727699"
        rpy="0 0 0" />
      <mass
        value="0.0143594964918226" />
      <inertia
        ixx="7.15388390483937E-06"
        ixy="-6.69701976384447E-11"
        ixz="-2.03395115704228E-07"
        iyy="6.87910901050402E-06"
        iyz="5.38324327216661E-12"
        izz="9.1475596956079E-07" />
    </inertial>
    <visual>
      <origin
        xyz="0 0 0"
        rpy="0 0 0" />
      <geometry>
        <mesh
          filename="package://biped_s4/meshes/l_thumb_distal_pitch.STL" />
      </geometry>
      <material
        name="">
        <color
          rgba="1 1 1 1" />
      </material>
    </visual>
    <collision>
      <origin
        xyz="0 0 0"
        rpy="0 0 0" />
      <geometry>
        <mesh
          filename="package://biped_s4/meshes/l_thumb_distal_pitch.STL" />
      </geometry>
    </collision>
  </link>
  <joint
    name="thumb2"
    type="revolute">
    <origin
      xyz="0.0120000000000023 -0.00649999999999773 0"
      rpy="0 0 0" />
    <parent
      link="thumb1" />
    <child
      link="thumb2" />
    <axis
      xyz="0 1 0" />
    <limit
      lower="-1.5708"
      upper="0"
      effort="0"
      velocity="0" />
  </joint>
  <link
    name="index1">
    <inertial>
      <origin
        xyz="0.000112677527646918 0.00210468432487104 -0.0171028451759692"
        rpy="0 0 0" />
      <mass
        value="0.00213736998836043" />
      <inertia
        ixx="3.18607074297438E-07"
        ixy="1.30056260562274E-09"
        ixz="2.05323306383889E-09"
        iyy="3.41865494200988E-07"
        iyz="3.87251682723715E-08"
        izz="9.68025640372966E-08" />
    </inertial>
    <visual>
      <origin
        xyz="0 0 0"
        rpy="0 0 0" />
      <geometry>
        <mesh
          filename="package://biped_s4/meshes/l_index_proximal_finger.STL" />
      </geometry>
      <material
        name="">
        <color
          rgba="1 1 1 1" />
      </material>
    </visual>
    <collision>
      <origin
        xyz="0 0 0"
        rpy="0 0 0" />
      <geometry>
        <mesh
          filename="package://biped_s4/meshes/l_index_proximal_finger.STL" />
      </geometry>
    </collision>
  </link>
  <joint
    name="index1"
    type="revolute">
    <origin
      xyz="0.0295025377507617 0.0039487923396046 -0.174730558860478"
      rpy="0 -0.0311675978215656 0" />
    <parent
      link="base_link" />
    <child
      link="index1" />
    <axis
      xyz="-0.998506141360648 0.0546395979585239 0" />
    <limit
      lower="0"
      upper="1.5708"
      effort="0"
      velocity="0" />
  </joint>
  <link
    name="index2">
    <inertial>
      <origin
        xyz="-8.80400428074002E-05 -0.00161951020344181 -0.0254571889170825"
        rpy="0 0 0" />
      <mass
        value="0.0050446595604151" />
      <inertia
        ixx="7.63510729443016E-07"
        ixy="9.29795250634311E-10"
        ixz="-1.77723934932869E-09"
        iyy="7.80114728886836E-07"
        iyz="-3.23075401001615E-08"
        izz="1.15370765338784E-07" />
    </inertial>
    <visual>
      <origin
        xyz="0 0 0"
        rpy="0 0 0" />
      <geometry>
        <mesh
          filename="package://biped_s4/meshes/l_index_distal_finger.STL" />
      </geometry>
      <material
        name="">
        <color
          rgba="1 1 1 1" />
      </material>
    </visual>
    <collision>
      <origin
        xyz="0 0 0"
        rpy="0 0 0" />
      <geometry>
        <mesh
          filename="package://biped_s4/meshes/l_index_distal_finger.STL" />
      </geometry>
    </collision>
  </link>
  <joint
    name="index2"
    type="revolute">
    <origin
      xyz="0.00013351949359549 0.00243998929947531 -0.0349145904281216"
      rpy="0 0 0" />
    <parent
      link="index1" />
    <child
      link="index2" />
    <axis
      xyz="0.998506141360648 -0.0546395979585221 0" />
    <limit
      lower="-1.5708"
      upper="0"
      effort="0"
      velocity="0" />
  </joint>
  <link
    name="middle1">
    <inertial>
      <origin
        xyz="-8.42681364791875E-08 0.00270210130078863 -0.0207829689336636"
        rpy="0 0 0" />
      <mass
        value="0.00260456391453855" />
      <inertia
        ixx="5.09608185934252E-07"
        ixy="-1.75213111801256E-12"
        ixz="-1.78265353217213E-12"
        iyy="5.36695797641851E-07"
        iyz="5.70433108286832E-08"
        izz="1.25808947550621E-07" />
    </inertial>
    <visual>
      <origin
        xyz="0 0 0"
        rpy="0 0 0" />
      <geometry>
        <mesh
          filename="package://biped_s4/meshes/l_middle_proximal_finger.STL" />
      </geometry>
      <material
        name="">
        <color
          rgba="1 1 1 1" />
      </material>
    </visual>
    <collision>
      <origin
        xyz="0 0 0"
        rpy="0 0 0" />
      <geometry>
        <mesh
          filename="package://biped_s4/meshes/l_middle_proximal_finger.STL" />
      </geometry>
    </collision>
  </link>
  <joint
    name="middle1"
    type="revolute">
    <origin
      xyz="0.00850000275976636 0.00820381922686209 -0.178435376742696"
      rpy="0 0 0" />
    <parent
      link="base_link" />
    <child
      link="middle1" />
    <axis
      xyz="-1 0 0" />
    <limit
      lower="0"
      upper="1.5708"
      effort="0"
      velocity="0" />
  </joint>
  <link
    name="middle2">
    <inertial>
      <origin
        xyz="6.04648922300846E-07 -0.00162350982455478 -0.0254571915129888"
        rpy="0 0 0" />
      <mass
        value="0.00504466861649399" />
      <inertia
        ixx="7.63455312842206E-07"
        ixy="1.85533672652204E-11"
        ixz="-1.04806627113088E-11"
        iyy="7.80159394341909E-07"
        iyz="-3.23975147926483E-08"
        izz="1.15374581207705E-07" />
    </inertial>
    <visual>
      <origin
        xyz="0 0 0"
        rpy="0 0 0" />
      <geometry>
        <mesh
          filename="package://biped_s4/meshes/l_middle_distal_finger.STL" />
      </geometry>
      <material
        name="">
        <color
          rgba="1 1 1 1" />
      </material>
    </visual>
    <collision>
      <origin
        xyz="0 0 0"
        rpy="0 0 0" />
      <geometry>
        <mesh
          filename="package://biped_s4/meshes/l_middle_distal_finger.STL" />
      </geometry>
    </collision>
  </link>
  <joint
    name="middle2"
    type="revolute">
    <origin
      xyz="0 0.00292977189725752 -0.0418976901109154"
      rpy="0 0 0" />
    <parent
      link="middle1" />
    <child
      link="middle2" />
    <axis
      xyz="1 0 0" />
    <limit
      lower="-1.5708"
      upper="0"
      effort="0"
      velocity="0" />
  </joint>
  <link
    name="ring1">
    <inertial>
      <origin
        xyz="-0.000147796548979496 0.00269934539278621 -0.0207828033089016"
        rpy="0 0 0" />
      <mass
        value="0.00260456483338844" />
      <inertia
        ixx="5.09689336813819E-07"
        ixy="-1.47916431111907E-09"
        ixz="-3.12001764447105E-09"
        iyy="5.36607842012435E-07"
        iyz="5.69834083724575E-08"
        izz="1.25816049307563E-07" />
    </inertial>
    <visual>
      <origin
        xyz="0 0 0"
        rpy="0 0 0" />
      <geometry>
        <mesh
          filename="package://biped_s4/meshes/l_ring_proximal_finger.STL" />
      </geometry>
      <material
        name="">
        <color
          rgba="1 1 1 1" />
      </material>
    </visual>
    <collision>
      <origin
        xyz="0 0 0"
        rpy="0 0 0" />
      <geometry>
        <mesh
          filename="package://biped_s4/meshes/l_ring_proximal_finger.STL" />
      </geometry>
    </collision>
  </link>
  <joint
    name="ring1"
    type="revolute">
    <origin
      xyz="-0.0126025322312212 0.0080785614881318 -0.176446661066021"
      rpy="0 0.0311675978215913 0" />
    <parent
      link="base_link" />
    <child
      link="ring1" />
    <axis
      xyz="-0.998506141360648 -0.0546395979585319 0" />
    <limit
      lower="0"
      upper="1.5708"
      effort="0"
      velocity="0" />
  </joint>
  <link
    name="ring2">
    <inertial>
      <origin
        xyz="-2.97819768621012E-05 0.000551723183689734 -0.0145820959398313"
        rpy="0 0 0" />
      <mass
        value="0.00182871318152307" />
      <inertia
        ixx="2.63516580484025E-07"
        ixy="-6.83151710625831E-10"
        ixz="3.36133845950725E-10"
        iyy="2.75945893486764E-07"
        iyz="-6.18248894827772E-09"
        izz="4.69859277660983E-08" />
    </inertial>
    <visual>
      <origin
        xyz="0 0 0"
        rpy="0 0 0" />
      <geometry>
        <mesh
          filename="package://biped_s4/meshes/l_ring_distal_finger.STL" />
      </geometry>
      <material
        name="">
        <color
          rgba="1 1 1 1" />
      </material>
    </visual>
    <collision>
      <origin
        xyz="0 0 0"
        rpy="0 0 0" />
      <geometry>
        <mesh
          filename="package://biped_s4/meshes/l_ring_distal_finger.STL" />
      </geometry>
    </collision>
  </link>
  <joint
    name="ring2"
    type="revolute">
    <origin
      xyz="-0.000160223392310654 0.0029279871592986 -0.0418975085137674"
      rpy="0 0 0" />
    <parent
      link="ring1" />
    <child
      link="ring2" />
    <axis
      xyz="0.998506141360637 0.0546395979587272 0" />
    <limit
      lower="-1.5708"
      upper="0"
      effort="0"
      velocity="0" />
  </joint>
  <link
    name="little1">
    <inertial>
      <origin
        xyz="-0.000122637015400211 0.00210212976760699 -0.0171030805340099"
        rpy="0 0 0" />
      <mass
        value="0.00213737962233864" />
      <inertia
        ixx="3.18608415490598E-07"
        ixy="-1.31059762777735E-09"
        ixz="-2.27735464077079E-09"
        iyy="3.41873917256528E-07"
        iyz="3.868353887277E-08"
        izz="9.67938996220609E-08" />
    </inertial>
    <visual>
      <origin
        xyz="0 0 0"
        rpy="0 0 0" />
      <geometry>
        <mesh
          filename="package://biped_s4/meshes/l_pinky_proximal_finger.STL" />
      </geometry>
      <material
        name="">
        <color
          rgba="1 1 1 1" />
      </material>
    </visual>
    <collision>
      <origin
        xyz="0 0 0"
        rpy="0 0 0" />
      <geometry>
        <mesh
          filename="package://biped_s4/meshes/l_pinky_proximal_finger.STL" />
      </geometry>
    </collision>
  </link>
  <joint
    name="little1"
    type="revolute">
    <origin
      xyz="-0.0332309186593585 0.00363387338808113 -0.170227008036839"
      rpy="0 0.0659957839625552 0" />
    <parent
      link="base_link" />
    <child
      link="little1" />
    <axis
      xyz="-0.998370307122329 -0.0570677654763681 0" />
    <limit
      lower="0"
      upper="1.5708"
      effort="0"
      velocity="0" />
  </joint>
  <link
    name="little2">
    <inertial>
      <origin
        xyz="-2.37672426811816E-05 0.000794235285774603 -0.012715032786375"
        rpy="0 0 0" />
      <mass
        value="0.00162997770027121" />
      <inertia
        ixx="1.83851165948758E-07"
        ixy="-6.07372921831439E-10"
        ixz="5.80097687729223E-10"
        iyy="1.94700358156753E-07"
        iyz="-1.32219889788332E-09"
        izz="3.94697814103924E-08" />
    </inertial>
    <visual>
      <origin
        xyz="0 0 0"
        rpy="0 0 0" />
      <geometry>
        <mesh
          filename="package://biped_s4/meshes/l_pinky_distal_finger.STL" />
      </geometry>
      <material
        name="">
        <color
          rgba="1 1 1 1" />
      </material>
    </visual>
    <collision>
      <origin
        xyz="0 0 0"
        rpy="0 0 0" />
      <geometry>
        <mesh
          filename="package://biped_s4/meshes/l_pinky_distal_finger.STL" />
      </geometry>
    </collision>
  </link>
  <joint
    name="little2"
    type="revolute">
    <origin
      xyz="-0.000139217094110203 0.00243552926671115 -0.0349148795758059"
      rpy="0 0 0" />
    <parent
      link="little1" />
    <child
      link="little2" />
    <axis
      xyz="0.998370307122341 0.0570677654761637 0" />
    <limit
      lower="-1.5708"
      upper="0"
      effort="0"
      velocity="0" />
  </joint>
</robot>
